Workbook

Sheet Datos
A1: Unidad de Negocio | B1: Asesor Comercial | C1: Ppto Dia | D1: Venta Dia | E1: Cumplimiento Dia | F1: Objetivo Plan 35 | G1: Numero de facturas | H1: Cumplimiento Plan 35 | I1: Falto | J1: Total Venta Unidad
A2: Colombina Helados | B2: 1108 CRISTIAN COTAZO | C2: 4268013.3 | D2: 223580 | E2: =D2/C2 | F2: 15 | G2: 2 | H2: =G2/F2 | I2: =F2-G2 | J2: =D2+D3 | K2: =IFERROR(VLOOKUP(B2,[1]Hoja1!$A$4:$B$48,2,),0)
A3: Colombina Helados | B3: 1109 NAVIA LOPEZ HAROLD | C3: 5782400 | D3: 2028947 | E3: =D3/C3 | F3: 15 | G3: 8 | H3: =G3/F3 | I3: =F3-G3 | K3: =IFERROR(VLOOKUP(B3,[1]Hoja1!$A$4:$B$48,2,),0)
A4: Sanin | B4: 1404 JHON JAIME SANCHEZ | C4: 3912073.1 | D4: 685009 | E4: =D4/C4 | F4: 35 | G4: 13 | H4: =G4/F4 | I4: =F4-G4 | J4: =SUM(D4:D11) | K4: =IFERROR(VLOOKUP(B4,[1]Hoja1!$A$4:$B$48,2,),0)
A5: Sanin | B5: 1406 KEVIN ALEXANDER ORTIZ BADOS | C5: 3557632.4 | D5: 351601 | E5: =D5/C5 | F5: 35 | G5: 5 | H5: =G5/F5 | I5: =F5-G5 | K5: =IFERROR(VLOOKUP(B5,[1]Hoja1!$A$4:$B$48,2,),0)
A6: Sanin Foraneo | B6: 1407 SANTIAGO OTERO | C6: 4352260.4 | D6: 1022481 | E6: =D6/C6 | F6: 25 | G6: 14 | H6: =G6/F6 | I6: =F6-G6 | K6: =IFERROR(VLOOKUP(B6,[1]Hoja1!$A$4:$B$48,2,),0)
A7: Sanin Foraneo | B7: 1410 JUAN MANUEL SILVA | C7: 2949191.4 | D7: 2255194 | E7: =D7/C7 | F7: 35 | G7: 27 | H7: =G7/F7 | I7: =F7-G7 | K7: =IFERROR(VLOOKUP(B7,[1]Hoja1!$A$4:$B$48,2,),0)
A8: Sanin | B8: 1411 BETANIA PEÑA | C8: 3599832.4 | D8: 526457 | E8: =D8/C8 | F8: 35 | G8: 14 | H8: =G8/F8 | I8: =F8-G8 | K8: =IFERROR(VLOOKUP(B8,[1]Hoja1!$A$4:$B$48,2,),0)
A9: Sanin | B9: 1412 JAIRO RUIZ | C9: 4051883.3 | D9: 3112600 | E9: =D9/C9 | F9: 25 | G9: 11 | H9: =G9/F9 | I9: =F9-G9 | K9: =IFERROR(VLOOKUP(B9,[1]Hoja1!$A$4:$B$48,2,),0)
A10: Sanin | B10: 1416 JOSE LUIS ARTEAGA | C10: 4501003.7 | D10: 1633262 | E10: =D10/C10 | F10: 35 | G10: 13 | H10: =G10/F10 | I10: =F10-G10 | K10: =IFERROR(VLOOKUP(B10,[1]Hoja1!$A$4:$B$48,2,),0)
A11: Sanin | B11: 1417 AREVALO DUARTE CARLOS ALBERTO | C11: 4068123.3 | D11: 394472 | E11: =D11/C11 | F11: 35 | G11: 6 | H11: =G11/F11 | I11: =F11-G11 | K11: =IFERROR(VLOOKUP(B11,[1]Hoja1!$A$4:$B$48,2,),0)
A12: Colombina | B12: 2001 LEYDI CAROLINA VICTORIA OJEDA | C12: 2115234.4 | D12: 73431 | E12: =D12/C12 | F12: 35 | G12: 1 | H12: =G12/F12 | I12: =F12-G12 | J12: =SUM(D12:D19) | K12: =IFERROR(VLOOKUP(B12,[1]Hoja1!$A$4:$B$48,2,),0)
A13: Colombina | B13: 2003 MAYI KATERINE PEREZ ORTIZ | C13: 2350449.4 | D13: 1408251 | E13: =D13/C13 | F13: 35 | G13: 16 | H13: =G13/F13 | I13: =F13-G13 | K13: =IFERROR(VLOOKUP(B13,[1]Hoja1!$A$4:$B$48,2,),0)
A14: Colombina | B14: 2004 NICOL CRUZ | C14: 2027779.2 | D14: 519632 | E14: =D14/C14 | F14: 35 | G14: 10 | H14: =G14/F14 | I14: =F14-G14 | K14: =IFERROR(VLOOKUP(B14,[1]Hoja1!$A$4:$B$48,2,),0)
A15: Colombina | B15: 2006 CRISTIAN CALLE | C15: 1995472.1 | D15: 526732 | E15: =D15/C15 | F15: 35 | G15: 11 | H15: =G15/F15 | I15: =F15-G15 | K15: =IFERROR(VLOOKUP(B15,[1]Hoja1!$A$4:$B$48,2,),0)
A16: Colombina Foraneo | B16: 4002 JUAN CAMILO SOTELO | C16: 2883608 | D16: 1574351 | E16: =D16/C16 | F16: 25 | G16: 10 | H16: =G16/F16 | I16: =F16-G16 | K16: =IFERROR(VLOOKUP(B16,[1]Hoja1!$A$4:$B$48,2,),0)
A17: Colombina | B17: 4006 LINA TRUJILLO | C17: 2192336.5 | D17: 1300154 | E17: =D17/C17 | F17: 35 | G17: 22 | H17: =G17/F17 | I17: =F17-G17 | K17: =IFERROR(VLOOKUP(B17,[1]Hoja1!$A$4:$B$48,2,),0)
A18: Colombina Foraneo | B18: 4007 ANGELA AMPUDIA MOLINA | C18: 2822450.2 | D18: 1744705 | E18: =D18/C18 | F18: 25 | G18: 19 | H18: =G18/F18 | I18: =F18-G18 | K18: =IFERROR(VLOOKUP(B18,[1]Hoja1!$A$4:$B$48,2,),0)
A19: Colombina | B19: 4009 STEPHANIE MUNÑOZ | C19: 1875070.1 | D19: 591233 | E19: =D19/C19 | F19: 35 | G19: 12 | H19: =G19/F19 | I19: =F19-G19 | K19: =IFERROR(VLOOKUP(B19,[1]Hoja1!$A$4:$B$48,2,),0)
A20: Casa Luker | B20: 6001 SUSANA NOGUERA | C20: 3489091.3 | D20: 984789 | E20: =D20/C20 | F20: 35 | G20: 18 | H20: =G20/F20 | I20: =F20-G20 | J20: =SUM(D20:D27) | K20: =IFERROR(VLOOKUP(B20,[1]Hoja1!$A$4:$B$48,2,),0)
A21: Casa Luker | B21: 6002 STEFANY ALEJANDRA VILLAREAL | C21: 2577874.3 | D21: 583371 | E21: =D21/C21 | F21: 35 | G21: 11 | H21: =G21/F21 | I21: =F21-G21 | K21: =IFERROR(VLOOKUP(B21,[1]Hoja1!$A$4:$B$48,2,),0)
A22: Casa Luker | B22: 6003 MAURICIO VIVAS RUIZ | C22: 4147681.2 | D22: 3327707 | E22: =D22/C22 | F22: 25 | G22: 8 | H22: =G22/F22 | I22: =F22-G22 | K22: =IFERROR(VLOOKUP(B22,[1]Hoja1!$A$4:$B$48,2,),0)
A23: Casa Luker | B23: 6006 SANTIAGO IMBACHI JOAQUI | C23: 2540205.1 | D23: 784817 | E23: =D23/C23 | F23: 35 | G23: 15 | H23: =G23/F23 | I23: =F23-G23 | K23: =IFERROR(VLOOKUP(B23,[1]Hoja1!$A$4:$B$48,2,),0)
A24: Casa Luker foraneo | B24: 6007 MEYER MUÑOZ | C24: 3542990.1 | D24: 2322726 | E24: =D24/C24 | F24: 25 | G24: 16 | H24: =G24/F24 | I24: =F24-G24 | K24: =IFERROR(VLOOKUP(B24,[1]Hoja1!$A$4:$B$48,2,),0)
A25: Casa Luker Foraneo | B25: 6009 FABIO VERGARA | C25: 2920413.5 | D25: 869025 | E25: =D25/C25 | F25: 35 | G25: 13 | H25: =G25/F25 | I25: =F25-G25 | K25: =IFERROR(VLOOKUP(B25,[1]Hoja1!$A$4:$B$48,2,),0)
A26: Casa Luker | B26: 6010 ALEJANDRO CIFUENTES GAMBOA | C26: 2415122.6 | D26: 415912 | E26: =D26/C26 | F26: 35 | G26: 7 | H26: =G26/F26 | I26: =F26-G26 | K26: =IFERROR(VLOOKUP(B26,[1]Hoja1!$A$4:$B$48,2,),0)
A27: Casa Luker | B27: 6011 FERNANDO CHAGUENDO | C27: 4616221.9 | D27: 1920217 | E27: =D27/C27 | F27: 35 | G27: 8 | H27: =G27/F27 | I27: =F27-G27 | K27: =IFERROR(VLOOKUP(B27,[1]Hoja1!$A$4:$B$48,2,),0)
A28: Tecnoquimicas | B28: 9001 VICTOR MANUEL GEMBUEL YANDI | C28: 2620062.3 | D28: 562800 | E28: =D28/C28 | F28: 35 | G28: 13 | H28: =G28/F28 | I28: =F28-G28 | J28: =SUM(D28:D35) | K28: =IFERROR(VLOOKUP(B28,[1]Hoja1!$A$4:$B$48,2,),0)
A29: Tecnoquimicas | B29: 9002 SEBASTIAN MAURICIO MOSQUERA | C29: 2458438.6 | D29: 915675 | E29: =D29/C29 | F29: 35 | G29: 18 | H29: =G29/F29 | I29: =F29-G29 | K29: =IFERROR(VLOOKUP(B29,[1]Hoja1!$A$4:$B$48,2,),0)
A30: Tecnoquimicas Foraneo | B30: 9003 JUAN CAMILO PITO | C30: 2514139 | D30: 2400108 | E30: =D30/C30 | F30: 25 | G30: 16 | H30: =G30/F30 | I30: =F30-G30 | K30: =IFERROR(VLOOKUP(B30,[1]Hoja1!$A$4:$B$48,2,),0)
A31: Tecnoquimicas | B31: 9004 VICTOR CIFUENTES | C31: 2647652.7 | D31: 135262 | E31: =D31/C31 | F31: 35 | G31: 2 | H31: =G31/F31 | I31: =F31-G31 | K31: =IFERROR(VLOOKUP(B31,[1]Hoja1!$A$4:$B$48,2,),0)
A32: Tecnoquimicas | B32: 9006 LAURA INES GARCIA | C32: 2470680.8 | D32: 64164 | E32: =D32/C32 | F32: 35 | G32: 3 | H32: =G32/F32 | I32: =F32-G32 | K32: =IFERROR(VLOOKUP(B32,[1]Hoja1!$A$4:$B$48,2,),0)
A33: Tecnoquimicas Foraneo | B33: 9007 MARIA CRISTINA DIAZ | C33: 2270254.2 | D33: 1483330 | E33: =D33/C33 | F33: 25 | G33: 15 | H33: =G33/F33 | I33: =F33-G33 | K33: =IFERROR(VLOOKUP(B33,[1]Hoja1!$A$4:$B$48,2,),0)
A34: Tecnoquimicas | B34: 9008 DORIS ROSAS MONCADA | C34: 2328805.6 | D34: 296644 | E34: =D34/C34 | F34: 35 | G34: 7 | H34: =G34/F34 | I34: =F34-G34 | K34: =IFERROR(VLOOKUP(B34,[1]Hoja1!$A$4:$B$48,2,),0)
A35: Tecnoquimicas | B35: 9009 FREYDER SEBASTIAN ROSERO GOMEZ | C35: 1534766.8 | D35: 49563 | E35: =D35/C35 | F35: 35 | G35: 2 | H35: =G35/F35 | I35: =F35-G35 | K35: =IFERROR(VLOOKUP(B35,[1]Hoja1!$A$4:$B$48,2,),0)
A36: Clientes Especiales | B36: 9025 ANDERSON PAJOY | C36: 14768000 | D36: 8856753 | E36: =D36/C36 | F36: 10 | G36: 2 | H36: =G36/F36 | I36: =F36-G36 | J36: =D36 | K36: =IFERROR(VLOOKUP(B36,[1]Hoja1!$A$4:$B$48,2,),0)
A37: Brinsa | B37: 9040 ANGIE PAOLA CHAGUENDO | C37: 744134.19 | D37: 144725 | E37: =D37/C37 | F37: 25 | G37: 4 | H37: =G37/F37 | I37: =F37-G37 | J37: =SUM(D37:D44) | K37: =IFERROR(VLOOKUP(B37,[1]Hoja1!$A$4:$B$48,2,),0)
A38: Brinsa | B38: 9041 DAVID PERDOMO | C38: 744134.19 | D38: 135701 | E38: =D38/C38 | F38: 25 | G38: 5 | H38: =G38/F38 | I38: =F38-G38 | K38: =IFERROR(VLOOKUP(B38,[1]Hoja1!$A$4:$B$48,2,),0)
A39: Brinsa | B39: 9042 LEYDI CAROLINA ZUÑIGA CASTILLO | C39: 744134.19 | D39: 150873 | E39: =D39/C39 | F39: 25 | G39: 3 | H39: =G39/F39 | I39: =F39-G39 | K39: =IFERROR(VLOOKUP(B39,[1]Hoja1!$A$4:$B$48,2,),0)
A40: Brinsa | B40: 9044 ALEXANDRA ERAZO | C40: 744134.19 | D40: 76728 | E40: =D40/C40 | F40: 25 | G40: 2 | H40: =G40/F40 | I40: =F40-G40 | K40: =IFERROR(VLOOKUP(B40,[1]Hoja1!$A$4:$B$48,2,),0)
...

Sheet Dashboard General
B1: INFORME DE VENTAS — Abril 2025
B4: Dirección Comercial | 47 asesores activos | 8 unidades de negocio
B6: VENTA DÍA TOTAL | D6: PRESUPUESTO DÍA | F6: CUMPL. PRESUPUESTO | H6: CUMPL. PLAN PEDIDOS
B7: =TEXT(SUMIF(Datos!A2:A49,"<>"&"",Datos!D2:D49)/1000000,"$#,##0.00")&"M" | D7: =TEXT(SUMIF(Datos!A2:A49,"<>"&"",Datos!C2:C49)/1000000,"$#,##0.00")&"M" | F7: =TEXT(SUMIF(Datos!A2:A49,"<>"&"",Datos!D2:D49)/SUMIF(Datos!A2:A49,"<>"&"",Datos!C2:C49),"0.0%") | H7: =TEXT(SUMIF(Datos!A2:A49,"<>"&"",Datos!G2:G49)/SUMIF(Datos!A2:A49,"<>"&"",Datos!F2:F49),"0.0%")
B11: FACTURAS EMITIDAS | D11: ASESORES CUMPLEN META | F11: MEJOR UN (VENTA DÍA) | H11: UN CRÍTICA (CUMPL.)
B12: =TEXT(SUMIF(Datos!A2:A49,"<>"&"",Datos!G2:G49),"#,##0")&" / "&TEXT(SUMIF(Datos!A2:A49,"<>"&"",Datos!F2:F49),"#,##0") | D12: =TEXT(COUNTIF(Datos!E2:E49,">="&0.9),"0")&" / "&TEXT(COUNTA(Datos!B2:B49)-1,"0") | F12: =INDEX(Datos!A2:A49,MATCH(MAX(Datos!D2:D49),Datos!D2:D49,0)) | H12: =INDEX(Datos!A2:A49,MATCH(MIN(Datos!E2:E49),Datos!E2:E49,0))
B16: RESUMEN POR UNIDAD DE NEGOCIO
B17: Unidad de Negocio | C17: Asesores | D17: Presupuesto Día | E17: Venta Día | F17: % Cumpl. Ppto | G17: Facturas | H17: Obj. Plan | I17: % Cumpl. Plan
B18: Sanin | C18: 8 | D18: =Datos!C4+Datos!C5+Datos!C6+Datos!C7+Datos!C8+Datos!C9+Datos!C10+Datos!C11 | E18: =Datos!D4+Datos!D5+Datos!D6+Datos!D7+Datos!D8+Datos!D9+Datos!D10+Datos!D11 | F18: =E18/D18 | G18: =Datos!G4+Datos!G5+Datos!G6+Datos!G7+Datos!G8+Datos!G9+Datos!G10+Datos!G11 | H18: =Datos!F4+Datos!F5+Datos!F6+Datos!F7+Datos!F8+Datos!F9+Datos!F10+Datos!F11 | I18: =G18/H18
B19: Casa Luker | C19: 8 | D19: =Datos!C20+Datos!C21+Datos!C22+Datos!C23+Datos!C24+Datos!C25+Datos!C26+Datos!C27 | E19: =Datos!D20+Datos!D21+Datos!D22+Datos!D23+Datos!D24+Datos!D25+Datos!D26+Datos!D27 | F19: =E19/D19 | G19: =Datos!G20+Datos!G21+Datos!G22+Datos!G23+Datos!G24+Datos!G25+Datos!G26+Datos!G27 | H19: =Datos!F20+Datos!F21+Datos!F22+Datos!F23+Datos!F24+Datos!F25+Datos!F26+Datos!F27 | I19: =G19/H19
B20: Colombina | C20: 8 | D20: =Datos!C12+Datos!C13+Datos!C14+Datos!C15+Datos!C16+Datos!C17+Datos!C18+Datos!C19 | E20: =Datos!D12+Datos!D13+Datos!D14+Datos!D15+Datos!D16+Datos!D17+Datos!D18+Datos!D19 | F20: =E20/D20 | G20: =Datos!G12+Datos!G13+Datos!G14+Datos!G15+Datos!G16+Datos!G17+Datos!G18+Datos!G19 | H20: =Datos!F12+Datos!F13+Datos!F14+Datos!F15+Datos!F16+Datos!F17+Datos!F18+Datos!F19 | I20: =G20/H20
B21: Tecnoquimicas | C21: 8 | D21: =Datos!C28+Datos!C29+Datos!C30+Datos!C31+Datos!C32+Datos!C33+Datos!C34+Datos!C35 | E21: =Datos!D28+Datos!D29+Datos!D30+Datos!D31+Datos!D32+Datos!D33+Datos!D34+Datos!D35 | F21: =E21/D21 | G21: =Datos!G28+Datos!G29+Datos!G30+Datos!G31+Datos!G32+Datos!G33+Datos!G34+Datos!G35 | H21: =Datos!F28+Datos!F29+Datos!F30+Datos!F31+Datos!F32+Datos!F33+Datos!F34+Datos!F35 | I21: =G21/H21
B22: Clientes Especiales | C22: 1 | D22: =Datos!C36 | E22: =Datos!D36 | F22: =E22/D22 | G22: =Datos!G36 | H22: =Datos!F36 | I22: =G22/H22
B23: Brinsa | C23: 8 | D23: =Datos!C37+Datos!C38+Datos!C39+Datos!C40+Datos!C41+Datos!C42+Datos!C43+Datos!C44 | E23: =Datos!D37+Datos!D38+Datos!D39+Datos!D40+Datos!D41+Datos!D42+Datos!D43+Datos!D44 | F23: =E23/D23 | G23: =Datos!G37+Datos!G38+Datos!G39+Datos!G40+Datos!G41+Datos!G42+Datos!G43+Datos!G44 | H23: =Datos!F37+Datos!F38+Datos!F39+Datos!F40+Datos!F41+Datos!F42+Datos!F43+Datos!F44 | I23: =G23/H23
B24: Colombina Helados | C24: 2 | D24: =Datos!C2+Datos!C3 | E24: =Datos!D2+Datos!D3 | F24: =E24/D24 | G24: =Datos!G2+Datos!G3 | H24: =Datos!F2+Datos!F3 | I24: =G24/H24
B25: Alimentos Polar | C25: 4 | D25: =Datos!C45+Datos!C46+Datos!C47+Datos!C48 | E25: =Datos!D45+Datos!D46+Datos!D47+Datos!D48 | F25: =E25/D25 | G25: =Datos!G45+Datos!G46+Datos!G47+Datos!G48 | H25: =Datos!F45+Datos!F46+Datos!F47+Datos!F48 | I25: =G25/H25
B26: TOTAL GENERAL | C26: =SUM(C18:C25) | D26: =SUM(D18:D25) | E26: =SUM(E18:E25) | F26: =E26/D26 | G26: =SUM(G18:G25) | H26: =SUM(H18:H25) | I26: =G26/H26

Sheet Detalle Asesores
B1: DETALLE ASESORES COMERCIALES
B4: Ordenado por unidad de negocio y venta día | Semáforo: verde ≥90% · amarillo ≥70% · naranja ≥50% · rojo <50%
B5: Unidad de Negocio | C5: Asesor | D5: Ppto Día ($) | E5: Venta Día ($) | F5: % Cumpl. Ppto | G5: # Facturas | H5: Obj. Plan | I5: Faltante | J5: % Cumpl. Plan
B6: Sanin | C6: =IF(ISNUMBER(VALUE(LEFT(Datos!B4,4))),MID(Datos!B4,6,100),Datos!B4) | D6: =Datos!C4 | E6: =Datos!D4 | F6: =Datos!E4 | G6: =Datos!G4 | H6: =Datos!F4 | I6: =Datos!I4 | J6: =Datos!H4
B7: Sanin | C7: =IF(ISNUMBER(VALUE(LEFT(Datos!B5,4))),MID(Datos!B5,6,100),Datos!B5) | D7: =Datos!C5 | E7: =Datos!D5 | F7: =Datos!E5 | G7: =Datos!G5 | H7: =Datos!F5 | I7: =Datos!I5 | J7: =Datos!H5
B8: Sanin | C8: =IF(ISNUMBER(VALUE(LEFT(Datos!B6,4))),MID(Datos!B6,6,100),Datos!B6) | D8: =Datos!C6 | E8: =Datos!D6 | F8: =Datos!E6 | G8: =Datos!G6 | H8: =Datos!F6 | I8: =Datos!I6 | J8: =Datos!H6
B9: Sanin | C9: =IF(ISNUMBER(VALUE(LEFT(Datos!B7,4))),MID(Datos!B7,6,100),Datos!B7) | D9: =Datos!C7 | E9: =Datos!D7 | F9: =Datos!E7 | G9: =Datos!G7 | H9: =Datos!F7 | I9: =Datos!I7 | J9: =Datos!H7
B10: Sanin | C10: =IF(ISNUMBER(VALUE(LEFT(Datos!B8,4))),MID(Datos!B8,6,100),Datos!B8) | D10: =Datos!C8 | E10: =Datos!D8 | F10: =Datos!E8 | G10: =Datos!G8 | H10: =Datos!F8 | I10: =Datos!I8 | J10: =Datos!H8
B11: Sanin | C11: =IF(ISNUMBER(VALUE(LEFT(Datos!B9,4))),MID(Datos!B9,6,100),Datos!B9) | D11: =Datos!C9 | E11: =Datos!D9 | F11: =Datos!E9 | G11: =Datos!G9 | H11: =Datos!F9 | I11: =Datos!I9 | J11: =Datos!H9
B12: Sanin | C12: =IF(ISNUMBER(VALUE(LEFT(Datos!B10,4))),MID(Datos!B10,6,100),Datos!B10) | D12: =Datos!C10 | E12: =Datos!D10 | F12: =Datos!E10 | G12: =Datos!G10 | H12: =Datos!F10 | I12: =Datos!I10 | J12: =Datos!H10
B13: Sanin | C13: =IF(ISNUMBER(VALUE(LEFT(Datos!B11,4))),MID(Datos!B11,6,100),Datos!B11) | D13: =Datos!C11 | E13: =Datos!D11 | F13: =Datos!E11 | G13: =Datos!G11 | H13: =Datos!F11 | I13: =Datos!I11 | J13: =Datos!H11
B14: TOTAL SANIN | D14: =SUM(D6:D13) | E14: =SUM(E6:E13) | F14: =E14/D14 | G14: =SUM(G6:G13) | H14: =SUM(H6:H13) | I14: =SUM(I6:I13) | J14: =G14/H14
B15: Casa Luker | C15: =IF(ISNUMBER(VALUE(LEFT(Datos!B20,4))),MID(Datos!B20,6,100),Datos!B20) | D15: =Datos!C20 | E15: =Datos!D20 | F15: =Datos!E20 | G15: =Datos!G20 | H15: =Datos!F20 | I15: =Datos!I20 | J15: =Datos!H20
B16: Casa Luker | C16: =IF(ISNUMBER(VALUE(LEFT(Datos!B21,4))),MID(Datos!B21,6,100),Datos!B21) | D16: =Datos!C21 | E16: =Datos!D21 | F16: =Datos!E21 | G16: =Datos!G21 | H16: =Datos!F21 | I16: =Datos!I21 | J16: =Datos!H21
B17: Casa Luker | C17: =IF(ISNUMBER(VALUE(LEFT(Datos!B22,4))),MID(Datos!B22,6,100),Datos!B22) | D17: =Datos!C22 | E17: =Datos!D22 | F17: =Datos!E22 | G17: =Datos!G22 | H17: =Datos!F22 | I17: =Datos!I22 | J17: =Datos!H22
B18: Casa Luker | C18: =IF(ISNUMBER(VALUE(LEFT(Datos!B23,4))),MID(Datos!B23,6,100),Datos!B23) | D18: =Datos!C23 | E18: =Datos!D23 | F18: =Datos!E23 | G18: =Datos!G23 | H18: =Datos!F23 | I18: =Datos!I23 | J18: =Datos!H23
B19: Casa Luker | C19: =IF(ISNUMBER(VALUE(LEFT(Datos!B24,4))),MID(Datos!B24,6,100),Datos!B24) | D19: =Datos!C24 | E19: =Datos!D24 | F19: =Datos!E24 | G19: =Datos!G24 | H19: =Datos!F24 | I19: =Datos!I24 | J19: =Datos!H24
B20: Casa Luker | C20: =IF(ISNUMBER(VALUE(LEFT(Datos!B25,4))),MID(Datos!B25,6,100),Datos!B25) | D20: =Datos!C25 | E20: =Datos!D25 | F20: =Datos!E25 | G20: =Datos!G25 | H20: =Datos!F25 | I20: =Datos!I25 | J20: =Datos!H25
B21: Casa Luker | C21: =IF(ISNUMBER(VALUE(LEFT(Datos!B26,4))),MID(Datos!B26,6,100),Datos!B26) | D21: =Datos!C26 | E21: =Datos!D26 | F21: =Datos!E26 | G21: =Datos!G26 | H21: =Datos!F26 | I21: =Datos!I26 | J21: =Datos!H26
B22: Casa Luker | C22: =IF(ISNUMBER(VALUE(LEFT(Datos!B27,4))),MID(Datos!B27,6,100),Datos!B27) | D22: =Datos!C27 | E22: =Datos!D27 | F22: =Datos!E27 | G22: =Datos!G27 | H22: =Datos!F27 | I22: =Datos!I27 | J22: =Datos!H27
B23: TOTAL CASA LUKER | D23: =SUM(D15:D22) | E23: =SUM(E15:E22) | F23: =E23/D23 | G23: =SUM(G15:G22) | H23: =SUM(H15:H22) | I23: =SUM(I15:I22) | J23: =G23/H23
B24: Colombina | C24: =IF(ISNUMBER(VALUE(LEFT(Datos!B12,4))),MID(Datos!B12,6,100),Datos!B12) | D24: =Datos!C12 | E24: =Datos!D12 | F24: =Datos!E12 | G24: =Datos!G12 | H24: =Datos!F12 | I24: =Datos!I12 | J24: =Datos!H12
B25: Colombina | C25: =IF(ISNUMBER(VALUE(LEFT(Datos!B13,4))),MID(Datos!B13,6,100),Datos!B13) | D25: =Datos!C13 | E25: =Datos!D13 | F25: =Datos!E13 | G25: =Datos!G13 | H25: =Datos!F13 | I25: =Datos!I13 | J25: =Datos!H13
B26: Colombina | C26: =IF(ISNUMBER(VALUE(LEFT(Datos!B14,4))),MID(Datos!B14,6,100),Datos!B14) | D26: =Datos!C14 | E26: =Datos!D14 | F26: =Datos!E14 | G26: =Datos!G14 | H26: =Datos!F14 | I26: =Datos!I14 | J26: =Datos!H14
B27: Colombina | C27: =IF(ISNUMBER(VALUE(LEFT(Datos!B15,4))),MID(Datos!B15,6,100),Datos!B15) | D27: =Datos!C15 | E27: =Datos!D15 | F27: =Datos!E15 | G27: =Datos!G15 | H27: =Datos!F15 | I27: =Datos!I15 | J27: =Datos!H15
B28: Colombina | C28: =IF(ISNUMBER(VALUE(LEFT(Datos!B16,4))),MID(Datos!B16,6,100),Datos!B16) | D28: =Datos!C16 | E28: =Datos!D16 | F28: =Datos!E16 | G28: =Datos!G16 | H28: =Datos!F16 | I28: =Datos!I16 | J28: =Datos!H16
B29: Colombina | C29: =IF(ISNUMBER(VALUE(LEFT(Datos!B17,4))),MID(Datos!B17,6,100),Datos!B17) | D29: =Datos!C17 | E29: =Datos!D17 | F29: =Datos!E17 | G29: =Datos!G17 | H29: =Datos!F17 | I29: =Datos!I17 | J29: =Datos!H17
B30: Colombina | C30: =IF(ISNUMBER(VALUE(LEFT(Datos!B18,4))),MID(Datos!B18,6,100),Datos!B18) | D30: =Datos!C18 | E30: =Datos!D18 | F30: =Datos!E18 | G30: =Datos!G18 | H30: =Datos!F18 | I30: =Datos!I18 | J30: =Datos!H18
B31: Colombina | C31: =IF(ISNUMBER(VALUE(LEFT(Datos!B19,4))),MID(Datos!B19,6,100),Datos!B19) | D31: =Datos!C19 | E31: =Datos!D19 | F31: =Datos!E19 | G31: =Datos!G19 | H31: =Datos!F19 | I31: =Datos!I19 | J31: =Datos!H19
B32: TOTAL COLOMBINA | D32: =SUM(D24:D31) | E32: =SUM(E24:E31) | F32: =E32/D32 | G32: =SUM(G24:G31) | H32: =SUM(H24:H31) | I32: =SUM(I24:I31) | J32: =G32/H32
B33: Tecnoquimicas | C33: =IF(ISNUMBER(VALUE(LEFT(Datos!B28,4))),MID(Datos!B28,6,100),Datos!B28) | D33: =Datos!C28 | E33: =Datos!D28 | F33: =Datos!E28 | G33: =Datos!G28 | H33: =Datos!F28 | I33: =Datos!I28 | J33: =Datos!H28
B34: Tecnoquimicas | C34: =IF(ISNUMBER(VALUE(LEFT(Datos!B29,4))),MID(Datos!B29,6,100),Datos!B29) | D34: =Datos!C29 | E34: =Datos!D29 | F34: =Datos!E29 | G34: =Datos!G29 | H34: =Datos!F29 | I34: =Datos!I29 | J34: =Datos!H29
B35: Tecnoquimicas | C35: =IF(ISNUMBER(VALUE(LEFT(Datos!B30,4))),MID(Datos!B30,6,100),Datos!B30) | D35: =Datos!C30 | E35: =Datos!D30 | F35: =Datos!E30 | G35: =Datos!G30 | H35: =Datos!F30 | I35: =Datos!I30 | J35: =Datos!H30
B36: Tecnoquimicas | C36: =IF(ISNUMBER(VALUE(LEFT(Datos!B31,4))),MID(Datos!B31,6,100),Datos!B31) | D36: =Datos!C31 | E36: =Datos!D31 | F36: =Datos!E31 | G36: =Datos!G31 | H36: =Datos!F31 | I36: =Datos!I31 | J36: =Datos!H31
B37: Tecnoquimicas | C37: =IF(ISNUMBER(VALUE(LEFT(Datos!B32,4))),MID(Datos!B32,6,100),Datos!B32) | D37: =Datos!C32 | E37: =Datos!D32 | F37: =Datos!E32 | G37: =Datos!G32 | H37: =Datos!F32 | I37: =Datos!I32 | J37: =Datos!H32
B38: Tecnoquimicas | C38: =IF(ISNUMBER(VALUE(LEFT(Datos!B33,4))),MID(Datos!B33,6,100),Datos!B33) | D38: =Datos!C33 | E38: =Datos!D33 | F38: =Datos!E33 | G38: =Datos!G33 | H38: =Datos!F33 | I38: =Datos!I33 | J38: =Datos!H33
B39: Tecnoquimicas | C39: =IF(ISNUMBER(VALUE(LEFT(Datos!B34,4))),MID(Datos!B34,6,100),Datos!B34) | D39: =Datos!C34 | E39: =Datos!D34 | F39: =Datos!E34 | G39: =Datos!G34 | H39: =Datos!F34 | I39: =Datos!I34 | J39: =Datos!H34
B40: Tecnoquimicas | C40: =IF(ISNUMBER(VALUE(LEFT(Datos!B35,4))),MID(Datos!B35,6,100),Datos!B35) | D40: =Datos!C35 | E40: =Datos!D35 | F40: =Datos!E35 | G40: =Datos!G35 | H40: =Datos!F35 | I40: =Datos!I35 | J40: =Datos!H35
B41: TOTAL TECNOQUIMICAS | D41: =SUM(D33:D40) | E41: =SUM(E33:E40) | F41: =E41/D41 | G41: =SUM(G33:G40) | H41: =SUM(H33:H40) | I41: =SUM(I33:I40) | J41: =G41/H41
B42: Clientes Especiales | C42: =IF(ISNUMBER(VALUE(LEFT(Datos!B36,4))),MID(Datos!B36,6,100),Datos!B36) | D42: =Datos!C36 | E42: =Datos!D36 | F42: =Datos!E36 | G42: =Datos!G36 | H42: =Datos!F36 | I42: =Datos!I36 | J42: =Datos!H36
...

Sheet Sanin
B1: UNIDAD DE NEGOCIO — SANIN
B4: Corte: MARZO 2025 | Asesores: 8 | Informe automático
B6: VENTA DÍA | D6: PRESUPUESTO DÍA | F6: % CUMPL. PPTO | H6: % CUMPL. PLAN
B7: =TEXT((Datos!D4+Datos!D5+Datos!D6+Datos!D7+Datos!D8+Datos!D9+Datos!D10+Datos!D11)/1000000,"$#,##0.00")&"M" | D7: =TEXT((Datos!C4+Datos!C5+Datos!C6+Datos!C7+Datos!C8+Datos!C9+Datos!C10+Datos!C11)/1000000,"$#,##0.00")&"M" | F7: =TEXT((Datos!D4+Datos!D5+Datos!D6+Datos!D7+Datos!D8+Datos!D9+Datos!D10+Datos!D11)/(Datos!C4+Datos!C5+Datos!C6+Datos!C7+Datos!C8+Datos!C9+Datos!C10+Datos!C11),"0.0%") | H7: =TEXT((Datos!G4+Datos!G5+Datos!G6+Datos!G7+Datos!G8+Datos!G9+Datos!G10+Datos!G11)/(Datos!F4+Datos!F5+Datos!F6+Datos!F7+Datos!F8+Datos!F9+Datos!F10+Datos!F11),"0.0%")
B11: FACTURAS / OBJETIVO | D11: CUMPLEN META PLAN | F11: MEJOR ASESOR | H11: PEDIDOS FALTANTES
B12: =TEXT(Datos!G4+Datos!G5+Datos!G6+Datos!G7+Datos!G8+Datos!G9+Datos!G10+Datos!G11,"0")&" / "&TEXT(Datos!F4+Datos!F5+Datos!F6+Datos!F7+Datos!F8+Datos!F9+Datos!F10+Datos!F11,"0") | D12: =TEXT(COUNTIF(Datos!H4:H11,">="&1),"0")&" / "&"8" | F12: =IF(ISNUMBER(VALUE(LEFT(INDEX(Datos!B4:B11,MATCH(MAX(Datos!D4:D11),Datos!D4:D11,0)),4))),MID(INDEX(Datos!B4:B11,MATCH(MAX(Datos!D4:D11),Datos!D4:D11,0)),6,100),INDEX(Datos!B4:B11,MATCH(MAX(Datos!D4:D11),Datos!D4:D11,0))) | H12: =TEXT(ABS(Datos!F4+Datos!F5+Datos!F6+Datos!F7+Datos!F8+Datos!F9+Datos!F10+Datos!F11-Datos!G4+Datos!G5+Datos!G6+Datos!G7+Datos!G8+Datos!G9+Datos!G10+Datos!G11),"0")&IF(Datos!G4+Datos!G5+Datos!G6+Datos!G7+Datos!G8+Datos!G9+Datos!G10+Datos!G11>=Datos!F4+Datos!F5+Datos!F6+Datos!F7+Datos!F8+Datos!F9+Datos!F10+Datos!F11," excedente"," pedidos")
B16: DETALLE DE ASESORES — SANIN
B17: Asesor Comercial | C17: Ppto Día ($) | D17: Venta Día ($) | E17: % Cumpl. Ppto | F17: # Facturas | G17: Obj. Plan | H17: Faltante | I17: Estado Plan
B18: =IF(ISNUMBER(VALUE(LEFT(Datos!B4,4))),MID(Datos!B4,6,100),Datos!B4) | C18: =Datos!C4 | D18: =Datos!D4 | E18: =Datos!E4 | F18: =Datos!G4 | G18: =Datos!F4 | H18: =Datos!I4 | I18: =IF(Datos!E4>=0.9,"🟢 EXCELENTE",IF(Datos!E4>=0.7,"🟡 EN CAMINO",IF(Datos!E4>=0.5,"🟠 ALERTA","🔴 CRÍTICO")))
B19: =IF(ISNUMBER(VALUE(LEFT(Datos!B5,4))),MID(Datos!B5,6,100),Datos!B5) | C19: =Datos!C5 | D19: =Datos!D5 | E19: =Datos!E5 | F19: =Datos!G5 | G19: =Datos!F5 | H19: =Datos!I5 | I19: =IF(Datos!E5>=0.9,"🟢 EXCELENTE",IF(Datos!E5>=0.7,"🟡 EN CAMINO",IF(Datos!E5>=0.5,"🟠 ALERTA","🔴 CRÍTICO")))
B20: =IF(ISNUMBER(VALUE(LEFT(Datos!B6,4))),MID(Datos!B6,6,100),Datos!B6) | C20: =Datos!C6 | D20: =Datos!D6 | E20: =Datos!E6 | F20: =Datos!G6 | G20: =Datos!F6 | H20: =Datos!I6 | I20: =IF(Datos!E6>=0.9,"🟢 EXCELENTE",IF(Datos!E6>=0.7,"🟡 EN CAMINO",IF(Datos!E6>=0.5,"🟠 ALERTA","🔴 CRÍTICO")))
B21: =IF(ISNUMBER(VALUE(LEFT(Datos!B7,4))),MID(Datos!B7,6,100),Datos!B7) | C21: =Datos!C7 | D21: =Datos!D7 | E21: =Datos!E7 | F21: =Datos!G7 | G21: =Datos!F7 | H21: =Datos!I7 | I21: =IF(Datos!E7>=0.9,"🟢 EXCELENTE",IF(Datos!E7>=0.7,"🟡 EN CAMINO",IF(Datos!E7>=0.5,"🟠 ALERTA","🔴 CRÍTICO")))
B22: =IF(ISNUMBER(VALUE(LEFT(Datos!B8,4))),MID(Datos!B8,6,100),Datos!B8) | C22: =Datos!C8 | D22: =Datos!D8 | E22: =Datos!E8 | F22: =Datos!G8 | G22: =Datos!F8 | H22: =Datos!I8 | I22: =IF(Datos!E8>=0.9,"🟢 EXCELENTE",IF(Datos!E8>=0.7,"🟡 EN CAMINO",IF(Datos!E8>=0.5,"🟠 ALERTA","🔴 CRÍTICO")))
B23: =IF(ISNUMBER(VALUE(LEFT(Datos!B9,4))),MID(Datos!B9,6,100),Datos!B9) | C23: =Datos!C9 | D23: =Datos!D9 | E23: =Datos!E9 | F23: =Datos!G9 | G23: =Datos!F9 | H23: =Datos!I9 | I23: =IF(Datos!E9>=0.9,"🟢 EXCELENTE",IF(Datos!E9>=0.7,"🟡 EN CAMINO",IF(Datos!E9>=0.5,"🟠 ALERTA","🔴 CRÍTICO")))
B24: =IF(ISNUMBER(VALUE(LEFT(Datos!B10,4))),MID(Datos!B10,6,100),Datos!B10) | C24: =Datos!C10 | D24: =Datos!D10 | E24: =Datos!E10 | F24: =Datos!G10 | G24: =Datos!F10 | H24: =Datos!I10 | I24: =IF(Datos!E10>=0.9,"🟢 EXCELENTE",IF(Datos!E10>=0.7,"🟡 EN CAMINO",IF(Datos!E10>=0.5,"🟠 ALERTA","🔴 CRÍTICO")))
B25: =IF(ISNUMBER(VALUE(LEFT(Datos!B11,4))),MID(Datos!B11,6,100),Datos!B11) | C25: =Datos!C11 | D25: =Datos!D11 | E25: =Datos!E11 | F25: =Datos!G11 | G25: =Datos!F11 | H25: =Datos!I11 | I25: =IF(Datos!E11>=0.9,"🟢 EXCELENTE",IF(Datos!E11>=0.7,"🟡 EN CAMINO",IF(Datos!E11>=0.5,"🟠 ALERTA","🔴 CRÍTICO")))
B26: TOTAL SANIN | C26: =Datos!C4+Datos!C5+Datos!C6+Datos!C7+Datos!C8+Datos!C9+Datos!C10+Datos!C11 | D26: =Datos!D4+Datos!D5+Datos!D6+Datos!D7+Datos!D8+Datos!D9+Datos!D10+Datos!D11 | E26: =D26/C26 | F26: =Datos!G4+Datos!G5+Datos!G6+Datos!G7+Datos!G8+Datos!G9+Datos!G10+Datos!G11 | G26: =Datos!F4+Datos!F5+Datos!F6+Datos!F7+Datos!F8+Datos!F9+Datos!F10+Datos!F11 | H26: =SUM(H18:H25) | I26: =F26/G26
B28: ANÁLISIS DE GESTIÓN
B29: ="▶ Venta del día en progreso: "&TEXT((Datos!D4+Datos!D5+Datos!D6+Datos!D7+Datos!D8+Datos!D9+Datos!D10+Datos!D11)/(Datos!C4+Datos!C5+Datos!C6+Datos!C7+Datos!C8+Datos!C9+Datos!C10+Datos!C11),"0.0%")&" del presupuesto."
B30: =IF(COUNTIF(Datos!H4:H11,">="&1)=8,"✔ "&8&" de 8 asesores cumplen meta. Excedente de "&ABS((Datos!G4+Datos!G5+Datos!G6+Datos!G7+Datos!G8+Datos!G9+Datos!G10+Datos!G11)-(Datos!F4+Datos!F5+Datos!F6+Datos!F7+Datos!F8+Datos!F9+Datos!F10+Datos!F11))&" pedidos sobre el objetivo.","▶ "&COUNTIF(Datos!H4:H11,">="&1)&" de 8 asesores cumplen meta. Pendiente cerrar "&MAX(0,(Datos!F4+Datos!F5+Datos!F6+Datos!F7+Datos!F8+Datos!F9+Datos!F10+Datos!F11)-(Datos!G4+Datos!G5+Datos!G6+Datos!G7+Datos!G8+Datos!G9+Datos!G10+Datos!G11))&" pedidos.")
B31: ="★ Mejor asesor: "&IF(ISNUMBER(VALUE(LEFT(INDEX(Datos!B4:B11,MATCH(MAX(Datos!D4:D11),Datos!D4:D11,0)),4))),MID(INDEX(Datos!B4:B11,MATCH(MAX(Datos!D4:D11),Datos!D4:D11,0)),6,100),INDEX(Datos!B4:B11,MATCH(MAX(Datos!D4:D11),Datos!D4:D11,0)))&" con "&TEXT(MAX(Datos!D4:D11),"$#,##0")&" y "&INDEX(Datos!G4:G11,MATCH(MAX(Datos!D4:D11),Datos!D4:D11,0))&" facturas."
B32: ="⚠ Asesor con menor venta: "&IF(ISNUMBER(VALUE(LEFT(INDEX(Datos!B4:B11,MATCH(MIN(Datos!D4:D11),Datos!D4:D11,0)),4))),MID(INDEX(Datos!B4:B11,MATCH(MIN(Datos!D4:D11),Datos!D4:D11,0)),6,100),INDEX(Datos!B4:B11,MATCH(MIN(Datos!D4:D11),Datos!D4:D11,0)))&" con "&TEXT(MIN(Datos!D4:D11),"$#,##0")&" ("&TEXT(MIN(Datos!E4:E11),"0.0%")&" del ppto)."

Sheet Casa Luker
B1: UNIDAD DE NEGOCIO — CASA LUKER
B4: Corte: MARZO 2025 | Asesores: 8 | Informe automático
B6: VENTA DÍA | D6: PRESUPUESTO DÍA | F6: % CUMPL. PPTO | H6: % CUMPL. PLAN
B7: =TEXT((Datos!D20+Datos!D21+Datos!D22+Datos!D23+Datos!D24+Datos!D25+Datos!D26+Datos!D27)/1000000,"$#,##0.00")&"M" | D7: =TEXT((Datos!C20+Datos!C21+Datos!C22+Datos!C23+Datos!C24+Datos!C25+Datos!C26+Datos!C27)/1000000,"$#,##0.00")&"M" | F7: =TEXT((Datos!D20+Datos!D21+Datos!D22+Datos!D23+Datos!D24+Datos!D25+Datos!D26+Datos!D27)/(Datos!C20+Datos!C21+Datos!C22+Datos!C23+Datos!C24+Datos!C25+Datos!C26+Datos!C27),"0.0%") | H7: =TEXT((Datos!G20+Datos!G21+Datos!G22+Datos!G23+Datos!G24+Datos!G25+Datos!G26+Datos!G27)/(Datos!F20+Datos!F21+Datos!F22+Datos!F23+Datos!F24+Datos!F25+Datos!F26+Datos!F27),"0.0%")
B11: FACTURAS / OBJETIVO | D11: CUMPLEN META PLAN | F11: MEJOR ASESOR | H11: PEDIDOS FALTANTES
B12: =TEXT(Datos!G20+Datos!G21+Datos!G22+Datos!G23+Datos!G24+Datos!G25+Datos!G26+Datos!G27,"0")&" / "&TEXT(Datos!F20+Datos!F21+Datos!F22+Datos!F23+Datos!F24+Datos!F25+Datos!F26+Datos!F27,"0") | D12: =TEXT(COUNTIF(Datos!H20:H27,">="&1),"0")&" / "&"8" | F12: =IF(ISNUMBER(VALUE(LEFT(INDEX(Datos!B20:B27,MATCH(MAX(Datos!D20:D27),Datos!D20:D27,0)),4))),MID(INDEX(Datos!B20:B27,MATCH(MAX(Datos!D20:D27),Datos!D20:D27,0)),6,100),INDEX(Datos!B20:B27,MATCH(MAX(Datos!D20:D27),Datos!D20:D27,0))) | H12: =TEXT(ABS(Datos!F20+Datos!F21+Datos!F22+Datos!F23+Datos!F24+Datos!F25+Datos!F26+Datos!F27-Datos!G20+Datos!G21+Datos!G22+Datos!G23+Datos!G24+Datos!G25+Datos!G26+Datos!G27),"0")&IF(Datos!G20+Datos!G21+Datos!G22+Datos!G23+Datos!G24+Datos!G25+Datos!G26+Datos!G27>=Datos!F20+Datos!F21+Datos!F22+Datos!F23+Datos!F24+Datos!F25+Datos!F26+Datos!F27," excedente"," pedidos")
B16: DETALLE DE ASESORES — CASA LUKER
B17: Asesor Comercial | C17: Ppto Día ($) | D17: Venta Día ($) | E17: % Cumpl. Ppto | F17: # Facturas | G17: Obj. Plan | H17: Faltante | I17: Estado Plan
B18: =IF(ISNUMBER(VALUE(LEFT(Datos!B20,4))),MID(Datos!B20,6,100),Datos!B20) | C18: =Datos!C20 | D18: =Datos!D20 | E18: =Datos!E20 | F18: =Datos!G20 | G18: =Datos!F20 | H18: =Datos!I20 | I18: =IF(Datos!E20>=0.9,"🟢 EXCELENTE",IF(Datos!E20>=0.7,"🟡 EN CAMINO",IF(Datos!E20>=0.5,"🟠 ALERTA","🔴 CRÍTICO")))
B19: =IF(ISNUMBER(VALUE(LEFT(Datos!B21,4))),MID(Datos!B21,6,100),Datos!B21) | C19: =Datos!C21 | D19: =Datos!D21 | E19: =Datos!E21 | F19: =Datos!G21 | G19: =Datos!F21 | H19: =Datos!I21 | I19: =IF(Datos!E21>=0.9,"🟢 EXCELENTE",IF(Datos!E21>=0.7,"🟡 EN CAMINO",IF(Datos!E21>=0.5,"🟠 ALERTA","🔴 CRÍTICO")))
B20: =IF(ISNUMBER(VALUE(LEFT(Datos!B22,4))),MID(Datos!B22,6,100),Datos!B22) | C20: =Datos!C22 | D20: =Datos!D22 | E20: =Datos!E22 | F20: =Datos!G22 | G20: =Datos!F22 | H20: =Datos!I22 | I20: =IF(Datos!E22>=0.9,"🟢 EXCELENTE",IF(Datos!E22>=0.7,"🟡 EN CAMINO",IF(Datos!E22>=0.5,"🟠 ALERTA","🔴 CRÍTICO")))
B21: =IF(ISNUMBER(VALUE(LEFT(Datos!B23,4))),MID(Datos!B23,6,100),Datos!B23) | C21: =Datos!C23 | D21: =Datos!D23 | E21: =Datos!E23 | F21: =Datos!G23 | G21: =Datos!F23 | H21: =Datos!I23 | I21: =IF(Datos!E23>=0.9,"🟢 EXCELENTE",IF(Datos!E23>=0.7,"🟡 EN CAMINO",IF(Datos!E23>=0.5,"🟠 ALERTA","🔴 CRÍTICO")))
B22: =IF(ISNUMBER(VALUE(LEFT(Datos!B24,4))),MID(Datos!B24,6,100),Datos!B24) | C22: =Datos!C24 | D22: =Datos!D24 | E22: =Datos!E24 | F22: =Datos!G24 | G22: =Datos!F24 | H22: =Datos!I24 | I22: =IF(Datos!E24>=0.9,"🟢 EXCELENTE",IF(Datos!E24>=0.7,"🟡 EN CAMINO",IF(Datos!E24>=0.5,"🟠 ALERTA","🔴 CRÍTICO")))
B23: =IF(ISNUMBER(VALUE(LEFT(Datos!B25,4))),MID(Datos!B25,6,100),Datos!B25) | C23: =Datos!C25 | D23: =Datos!D25 | E23: =Datos!E25 | F23: =Datos!G25 | G23: =Datos!F25 | H23: =Datos!I25 | I23: =IF(Datos!E25>=0.9,"🟢 EXCELENTE",IF(Datos!E25>=0.7,"🟡 EN CAMINO",IF(Datos!E25>=0.5,"🟠 ALERTA","🔴 CRÍTICO")))
B24: =IF(ISNUMBER(VALUE(LEFT(Datos!B26,4))),MID(Datos!B26,6,100),Datos!B26) | C24: =Datos!C26 | D24: =Datos!D26 | E24: =Datos!E26 | F24: =Datos!G26 | G24: =Datos!F26 | H24: =Datos!I26 | I24: =IF(Datos!E26>=0.9,"🟢 EXCELENTE",IF(Datos!E26>=0.7,"🟡 EN CAMINO",IF(Datos!E26>=0.5,"🟠 ALERTA","🔴 CRÍTICO")))
B25: =IF(ISNUMBER(VALUE(LEFT(Datos!B27,4))),MID(Datos!B27,6,100),Datos!B27) | C25: =Datos!C27 | D25: =Datos!D27 | E25: =Datos!E27 | F25: =Datos!G27 | G25: =Datos!F27 | H25: =Datos!I27 | I25: =IF(Datos!E27>=0.9,"🟢 EXCELENTE",IF(Datos!E27>=0.7,"🟡 EN CAMINO",IF(Datos!E27>=0.5,"🟠 ALERTA","🔴 CRÍTICO")))
B26: TOTAL CASA LUKER | C26: =Datos!C20+Datos!C21+Datos!C22+Datos!C23+Datos!C24+Datos!C25+Datos!C26+Datos!C27 | D26: =Datos!D20+Datos!D21+Datos!D22+Datos!D23+Datos!D24+Datos!D25+Datos!D26+Datos!D27 | E26: =D26/C26 | F26: =Datos!G20+Datos!G21+Datos!G22+Datos!G23+Datos!G24+Datos!G25+Datos!G26+Datos!G27 | G26: =Datos!F20+Datos!F21+Datos!F22+Datos!F23+Datos!F24+Datos!F25+Datos!F26+Datos!F27 | H26: =SUM(H18:H25) | I26: =F26/G26
B28: ANÁLISIS DE GESTIÓN
B29: ="▶ Venta del día en progreso: "&TEXT((Datos!D20+Datos!D21+Datos!D22+Datos!D23+Datos!D24+Datos!D25+Datos!D26+Datos!D27)/(Datos!C20+Datos!C21+Datos!C22+Datos!C23+Datos!C24+Datos!C25+Datos!C26+Datos!C27),"0.0%")&" del presupuesto."
B30: =IF(COUNTIF(Datos!H20:H27,">="&1)=8,"✔ "&8&" de 8 asesores cumplen meta. Excedente de "&ABS((Datos!G20+Datos!G21+Datos!G22+Datos!G23+Datos!G24+Datos!G25+Datos!G26+Datos!G27)-(Datos!F20+Datos!F21+Datos!F22+Datos!F23+Datos!F24+Datos!F25+Datos!F26+Datos!F27))&" pedidos sobre el objetivo.","▶ "&COUNTIF(Datos!H20:H27,">="&1)&" de 8 asesores cumplen meta. Pendiente cerrar "&MAX(0,(Datos!F20+Datos!F21+Datos!F22+Datos!F23+Datos!F24+Datos!F25+Datos!F26+Datos!F27)-(Datos!G20+Datos!G21+Datos!G22+Datos!G23+Datos!G24+Datos!G25+Datos!G26+Datos!G27))&" pedidos.")
B31: ="★ Mejor asesor: "&IF(ISNUMBER(VALUE(LEFT(INDEX(Datos!B20:B27,MATCH(MAX(Datos!D20:D27),Datos!D20:D27,0)),4))),MID(INDEX(Datos!B20:B27,MATCH(MAX(Datos!D20:D27),Datos!D20:D27,0)),6,100),INDEX(Datos!B20:B27,MATCH(MAX(Datos!D20:D27),Datos!D20:D27,0)))&" con "&TEXT(MAX(Datos!D20:D27),"$#,##0")&" y "&INDEX(Datos!G20:G27,MATCH(MAX(Datos!D20:D27),Datos!D20:D27,0))&" facturas."
B32: ="⚠ Asesor con menor venta: "&IF(ISNUMBER(VALUE(LEFT(INDEX(Datos!B20:B27,MATCH(MIN(Datos!D20:D27),Datos!D20:D27,0)),4))),MID(INDEX(Datos!B20:B27,MATCH(MIN(Datos!D20:D27),Datos!D20:D27,0)),6,100),INDEX(Datos!B20:B27,MATCH(MIN(Datos!D20:D27),Datos!D20:D27,0)))&" con "&TEXT(MIN(Datos!D20:D27),"$#,##0")&" ("&TEXT(MIN(Datos!E20:E27),"0.0%")&" del ppto)."

Sheet Colombina
B1: UNIDAD DE NEGOCIO — COLOMBINA
B4: Corte: MARZO 2025 | Asesores: 8 | Informe automático
B6: VENTA DÍA | D6: PRESUPUESTO DÍA | F6: % CUMPL. PPTO | H6: % CUMPL. PLAN
B7: =TEXT((Datos!D12+Datos!D13+Datos!D14+Datos!D15+Datos!D16+Datos!D17+Datos!D18+Datos!D19)/1000000,"$#,##0.00")&"M" | D7: =TEXT((Datos!C12+Datos!C13+Datos!C14+Datos!C15+Datos!C16+Datos!C17+Datos!C18+Datos!C19)/1000000,"$#,##0.00")&"M" | F7: =TEXT((Datos!D12+Datos!D13+Datos!D14+Datos!D15+Datos!D16+Datos!D17+Datos!D18+Datos!D19)/(Datos!C12+Datos!C13+Datos!C14+Datos!C15+Datos!C16+Datos!C17+Datos!C18+Datos!C19),"0.0%") | H7: =TEXT((Datos!G12+Datos!G13+Datos!G14+Datos!G15+Datos!G16+Datos!G17+Datos!G18+Datos!G19)/(Datos!F12+Datos!F13+Datos!F14+Datos!F15+Datos!F16+Datos!F17+Datos!F18+Datos!F19),"0.0%")
B11: FACTURAS / OBJETIVO | D11: CUMPLEN META PLAN | F11: MEJOR ASESOR | H11: PEDIDOS FALTANTES
B12: =TEXT(Datos!G12+Datos!G13+Datos!G14+Datos!G15+Datos!G16+Datos!G17+Datos!G18+Datos!G19,"0")&" / "&TEXT(Datos!F12+Datos!F13+Datos!F14+Datos!F15+Datos!F16+Datos!F17+Datos!F18+Datos!F19,"0") | D12: =TEXT(COUNTIF(Datos!H12:H19,">="&1),"0")&" / "&"8" | F12: =IF(ISNUMBER(VALUE(LEFT(INDEX(Datos!B12:B19,MATCH(MAX(Datos!D12:D19),Datos!D12:D19,0)),4))),MID(INDEX(Datos!B12:B19,MATCH(MAX(Datos!D12:D19),Datos!D12:D19,0)),6,100),INDEX(Datos!B12:B19,MATCH(MAX(Datos!D12:D19),Datos!D12:D19,0))) | H12: =TEXT(ABS(Datos!F12+Datos!F13+Datos!F14+Datos!F15+Datos!F16+Datos!F17+Datos!F18+Datos!F19-Datos!G12+Datos!G13+Datos!G14+Datos!G15+Datos!G16+Datos!G17+Datos!G18+Datos!G19),"0")&IF(Datos!G12+Datos!G13+Datos!G14+Datos!G15+Datos!G16+Datos!G17+Datos!G18+Datos!G19>=Datos!F12+Datos!F13+Datos!F14+Datos!F15+Datos!F16+Datos!F17+Datos!F18+Datos!F19," excedente"," pedidos")
B16: DETALLE DE ASESORES — COLOMBINA
B17: Asesor Comercial | C17: Ppto Día ($) | D17: Venta Día ($) | E17: % Cumpl. Ppto | F17: # Facturas | G17: Obj. Plan | H17: Faltante | I17: Estado Plan
B18: =IF(ISNUMBER(VALUE(LEFT(Datos!B12,4))),MID(Datos!B12,6,100),Datos!B12) | C18: =Datos!C12 | D18: =Datos!D12 | E18: =Datos!E12 | F18: =Datos!G12 | G18: =Datos!F12 | H18: =Datos!I12 | I18: =IF(Datos!E12>=0.9,"🟢 EXCELENTE",IF(Datos!E12>=0.7,"🟡 EN CAMINO",IF(Datos!E12>=0.5,"🟠 ALERTA","🔴 CRÍTICO")))
B19: =IF(ISNUMBER(VALUE(LEFT(Datos!B13,4))),MID(Datos!B13,6,100),Datos!B13) | C19: =Datos!C13 | D19: =Datos!D13 | E19: =Datos!E13 | F19: =Datos!G13 | G19: =Datos!F13 | H19: =Datos!I13 | I19: =IF(Datos!E13>=0.9,"🟢 EXCELENTE",IF(Datos!E13>=0.7,"🟡 EN CAMINO",IF(Datos!E13>=0.5,"🟠 ALERTA","🔴 CRÍTICO")))
B20: =IF(ISNUMBER(VALUE(LEFT(Datos!B14,4))),MID(Datos!B14,6,100),Datos!B14) | C20: =Datos!C14 | D20: =Datos!D14 | E20: =Datos!E14 | F20: =Datos!G14 | G20: =Datos!F14 | H20: =Datos!I14 | I20: =IF(Datos!E14>=0.9,"🟢 EXCELENTE",IF(Datos!E14>=0.7,"🟡 EN CAMINO",IF(Datos!E14>=0.5,"🟠 ALERTA","🔴 CRÍTICO")))
B21: =IF(ISNUMBER(VALUE(LEFT(Datos!B15,4))),MID(Datos!B15,6,100),Datos!B15) | C21: =Datos!C15 | D21: =Datos!D15 | E21: =Datos!E15 | F21: =Datos!G15 | G21: =Datos!F15 | H21: =Datos!I15 | I21: =IF(Datos!E15>=0.9,"🟢 EXCELENTE",IF(Datos!E15>=0.7,"🟡 EN CAMINO",IF(Datos!E15>=0.5,"🟠 ALERTA","🔴 CRÍTICO")))
B22: =IF(ISNUMBER(VALUE(LEFT(Datos!B16,4))),MID(Datos!B16,6,100),Datos!B16) | C22: =Datos!C16 | D22: =Datos!D16 | E22: =Datos!E16 | F22: =Datos!G16 | G22: =Datos!F16 | H22: =Datos!I16 | I22: =IF(Datos!E16>=0.9,"🟢 EXCELENTE",IF(Datos!E16>=0.7,"🟡 EN CAMINO",IF(Datos!E16>=0.5,"🟠 ALERTA","🔴 CRÍTICO")))
B23: =IF(ISNUMBER(VALUE(LEFT(Datos!B17,4))),MID(Datos!B17,6,100),Datos!B17) | C23: =Datos!C17 | D23: =Datos!D17 | E23: =Datos!E17 | F23: =Datos!G17 | G23: =Datos!F17 | H23: =Datos!I17 | I23: =IF(Datos!E17>=0.9,"🟢 EXCELENTE",IF(Datos!E17>=0.7,"🟡 EN CAMINO",IF(Datos!E17>=0.5,"🟠 ALERTA","🔴 CRÍTICO")))
B24: =IF(ISNUMBER(VALUE(LEFT(Datos!B18,4))),MID(Datos!B18,6,100),Datos!B18) | C24: =Datos!C18 | D24: =Datos!D18 | E24: =Datos!E18 | F24: =Datos!G18 | G24: =Datos!F18 | H24: =Datos!I18 | I24: =IF(Datos!E18>=0.9,"🟢 EXCELENTE",IF(Datos!E18>=0.7,"🟡 EN CAMINO",IF(Datos!E18>=0.5,"🟠 ALERTA","🔴 CRÍTICO")))
B25: =IF(ISNUMBER(VALUE(LEFT(Datos!B19,4))),MID(Datos!B19,6,100),Datos!B19) | C25: =Datos!C19 | D25: =Datos!D19 | E25: =Datos!E19 | F25: =Datos!G19 | G25: =Datos!F19 | H25: =Datos!I19 | I25: =IF(Datos!E19>=0.9,"🟢 EXCELENTE",IF(Datos!E19>=0.7,"🟡 EN CAMINO",IF(Datos!E19>=0.5,"🟠 ALERTA","🔴 CRÍTICO")))
B26: TOTAL COLOMBINA | C26: =Datos!C12+Datos!C13+Datos!C14+Datos!C15+Datos!C16+Datos!C17+Datos!C18+Datos!C19 | D26: =Datos!D12+Datos!D13+Datos!D14+Datos!D15+Datos!D16+Datos!D17+Datos!D18+Datos!D19 | E26: =D26/C26 | F26: =Datos!G12+Datos!G13+Datos!G14+Datos!G15+Datos!G16+Datos!G17+Datos!G18+Datos!G19 | G26: =Datos!F12+Datos!F13+Datos!F14+Datos!F15+Datos!F16+Datos!F17+Datos!F18+Datos!F19 | H26: =SUM(H18:H25) | I26: =F26/G26
B28: ANÁLISIS DE GESTIÓN
B29: ="▶ Venta del día en progreso: "&TEXT((Datos!D12+Datos!D13+Datos!D14+Datos!D15+Datos!D16+Datos!D17+Datos!D18+Datos!D19)/(Datos!C12+Datos!C13+Datos!C14+Datos!C15+Datos!C16+Datos!C17+Datos!C18+Datos!C19),"0.0%")&" del presupuesto."
B30: =IF(COUNTIF(Datos!H12:H19,">="&1)=8,"✔ "&8&" de 8 asesores cumplen meta. Excedente de "&ABS((Datos!G12+Datos!G13+Datos!G14+Datos!G15+Datos!G16+Datos!G17+Datos!G18+Datos!G19)-(Datos!F12+Datos!F13+Datos!F14+Datos!F15+Datos!F16+Datos!F17+Datos!F18+Datos!F19))&" pedidos sobre el objetivo.","▶ "&COUNTIF(Datos!H12:H19,">="&1)&" de 8 asesores cumplen meta. Pendiente cerrar "&MAX(0,(Datos!F12+Datos!F13+Datos!F14+Datos!F15+Datos!F16+Datos!F17+Datos!F18+Datos!F19)-(Datos!G12+Datos!G13+Datos!G14+Datos!G15+Datos!G16+Datos!G17+Datos!G18+Datos!G19))&" pedidos.")
B31: ="★ Mejor asesor: "&IF(ISNUMBER(VALUE(LEFT(INDEX(Datos!B12:B19,MATCH(MAX(Datos!D12:D19),Datos!D12:D19,0)),4))),MID(INDEX(Datos!B12:B19,MATCH(MAX(Datos!D12:D19),Datos!D12:D19,0)),6,100),INDEX(Datos!B12:B19,MATCH(MAX(Datos!D12:D19),Datos!D12:D19,0)))&" con "&TEXT(MAX(Datos!D12:D19),"$#,##0")&" y "&INDEX(Datos!G12:G19,MATCH(MAX(Datos!D12:D19),Datos!D12:D19,0))&" facturas."
B32: ="⚠ Asesor con menor venta: "&IF(ISNUMBER(VALUE(LEFT(INDEX(Datos!B12:B19,MATCH(MIN(Datos!D12:D19),Datos!D12:D19,0)),4))),MID(INDEX(Datos!B12:B19,MATCH(MIN(Datos!D12:D19),Datos!D12:D19,0)),6,100),INDEX(Datos!B12:B19,MATCH(MIN(Datos!D12:D19),Datos!D12:D19,0)))&" con "&TEXT(MIN(Datos!D12:D19),"$#,##0")&" ("&TEXT(MIN(Datos!E12:E19),"0.0%")&" del ppto)."

Sheet Tecnoquimicas
B1: UNIDAD DE NEGOCIO — TECNOQUIMICAS
B4: Corte: MARZO 2025 | Asesores: 8 | Informe automático
B6: VENTA DÍA | D6: PRESUPUESTO DÍA | F6: % CUMPL. PPTO | H6: % CUMPL. PLAN
B7: =TEXT((Datos!D28+Datos!D29+Datos!D30+Datos!D31+Datos!D32+Datos!D33+Datos!D34+Datos!D35)/1000000,"$#,##0.00")&"M" | D7: =TEXT((Datos!C28+Datos!C29+Datos!C30+Datos!C31+Datos!C32+Datos!C33+Datos!C34+Datos!C35)/1000000,"$#,##0.00")&"M" | F7: =TEXT((Datos!D28+Datos!D29+Datos!D30+Datos!D31+Datos!D32+Datos!D33+Datos!D34+Datos!D35)/(Datos!C28+Datos!C29+Datos!C30+Datos!C31+Datos!C32+Datos!C33+Datos!C34+Datos!C35),"0.0%") | H7: =TEXT((Datos!G28+Datos!G29+Datos!G30+Datos!G31+Datos!G32+Datos!G33+Datos!G34+Datos!G35)/(Datos!F28+Datos!F29+Datos!F30+Datos!F31+Datos!F32+Datos!F33+Datos!F34+Datos!F35),"0.0%")
B11: FACTURAS / OBJETIVO | D11: CUMPLEN META PLAN | F11: MEJOR ASESOR | H11: PEDIDOS FALTANTES
B12: =TEXT(Datos!G28+Datos!G29+Datos!G30+Datos!G31+Datos!G32+Datos!G33+Datos!G34+Datos!G35,"0")&" / "&TEXT(Datos!F28+Datos!F29+Datos!F30+Datos!F31+Datos!F32+Datos!F33+Datos!F34+Datos!F35,"0") | D12: =TEXT(COUNTIF(Datos!H28:H35,">="&1),"0")&" / "&"8" | F12: =IF(ISNUMBER(VALUE(LEFT(INDEX(Datos!B28:B35,MATCH(MAX(Datos!D28:D35),Datos!D28:D35,0)),4))),MID(INDEX(Datos!B28:B35,MATCH(MAX(Datos!D28:D35),Datos!D28:D35,0)),6,100),INDEX(Datos!B28:B35,MATCH(MAX(Datos!D28:D35),Datos!D28:D35,0))) | H12: =TEXT(ABS(Datos!F28+Datos!F29+Datos!F30+Datos!F31+Datos!F32+Datos!F33+Datos!F34+Datos!F35-Datos!G28+Datos!G29+Datos!G30+Datos!G31+Datos!G32+Datos!G33+Datos!G34+Datos!G35),"0")&IF(Datos!G28+Datos!G29+Datos!G30+Datos!G31+Datos!G32+Datos!G33+Datos!G34+Datos!G35>=Datos!F28+Datos!F29+Datos!F30+Datos!F31+Datos!F32+Datos!F33+Datos!F34+Datos!F35," excedente"," pedidos")
B16: DETALLE DE ASESORES — TECNOQUIMICAS
B17: Asesor Comercial | C17: Ppto Día ($) | D17: Venta Día ($) | E17: % Cumpl. Ppto | F17: # Facturas | G17: Obj. Plan | H17: Faltante | I17: Estado Plan
B18: =IF(ISNUMBER(VALUE(LEFT(Datos!B28,4))),MID(Datos!B28,6,100),Datos!B28) | C18: =Datos!C28 | D18: =Datos!D28 | E18: =Datos!E28 | F18: =Datos!G28 | G18: =Datos!F28 | H18: =Datos!I28 | I18: =IF(Datos!E28>=0.9,"🟢 EXCELENTE",IF(Datos!E28>=0.7,"🟡 EN CAMINO",IF(Datos!E28>=0.5,"🟠 ALERTA","🔴 CRÍTICO")))
B19: =IF(ISNUMBER(VALUE(LEFT(Datos!B29,4))),MID(Datos!B29,6,100),Datos!B29) | C19: =Datos!C29 | D19: =Datos!D29 | E19: =Datos!E29 | F19: =Datos!G29 | G19: =Datos!F29 | H19: =Datos!I29 | I19: =IF(Datos!E29>=0.9,"🟢 EXCELENTE",IF(Datos!E29>=0.7,"🟡 EN CAMINO",IF(Datos!E29>=0.5,"🟠 ALERTA","🔴 CRÍTICO")))
B20: =IF(ISNUMBER(VALUE(LEFT(Datos!B30,4))),MID(Datos!B30,6,100),Datos!B30) | C20: =Datos!C30 | D20: =Datos!D30 | E20: =Datos!E30 | F20: =Datos!G30 | G20: =Datos!F30 | H20: =Datos!I30 | I20: =IF(Datos!E30>=0.9,"🟢 EXCELENTE",IF(Datos!E30>=0.7,"🟡 EN CAMINO",IF(Datos!E30>=0.5,"🟠 ALERTA","🔴 CRÍTICO")))
B21: =IF(ISNUMBER(VALUE(LEFT(Datos!B31,4))),MID(Datos!B31,6,100),Datos!B31) | C21: =Datos!C31 | D21: =Datos!D31 | E21: =Datos!E31 | F21: =Datos!G31 | G21: =Datos!F31 | H21: =Datos!I31 | I21: =IF(Datos!E31>=0.9,"🟢 EXCELENTE",IF(Datos!E31>=0.7,"🟡 EN CAMINO",IF(Datos!E31>=0.5,"🟠 ALERTA","🔴 CRÍTICO")))
B22: =IF(ISNUMBER(VALUE(LEFT(Datos!B32,4))),MID(Datos!B32,6,100),Datos!B32) | C22: =Datos!C32 | D22: =Datos!D32 | E22: =Datos!E32 | F22: =Datos!G32 | G22: =Datos!F32 | H22: =Datos!I32 | I22: =IF(Datos!E32>=0.9,"🟢 EXCELENTE",IF(Datos!E32>=0.7,"🟡 EN CAMINO",IF(Datos!E32>=0.5,"🟠 ALERTA","🔴 CRÍTICO")))
B23: =IF(ISNUMBER(VALUE(LEFT(Datos!B33,4))),MID(Datos!B33,6,100),Datos!B33) | C23: =Datos!C33 | D23: =Datos!D33 | E23: =Datos!E33 | F23: =Datos!G33 | G23: =Datos!F33 | H23: =Datos!I33 | I23: =IF(Datos!E33>=0.9,"🟢 EXCELENTE",IF(Datos!E33>=0.7,"🟡 EN CAMINO",IF(Datos!E33>=0.5,"🟠 ALERTA","🔴 CRÍTICO")))
B24: =IF(ISNUMBER(VALUE(LEFT(Datos!B34,4))),MID(Datos!B34,6,100),Datos!B34) | C24: =Datos!C34 | D24: =Datos!D34 | E24: =Datos!E34 | F24: =Datos!G34 | G24: =Datos!F34 | H24: =Datos!I34 | I24: =IF(Datos!E34>=0.9,"🟢 EXCELENTE",IF(Datos!E34>=0.7,"🟡 EN CAMINO",IF(Datos!E34>=0.5,"🟠 ALERTA","🔴 CRÍTICO")))
B25: =IF(ISNUMBER(VALUE(LEFT(Datos!B35,4))),MID(Datos!B35,6,100),Datos!B35) | C25: =Datos!C35 | D25: =Datos!D35 | E25: =Datos!E35 | F25: =Datos!G35 | G25: =Datos!F35 | H25: =Datos!I35 | I25: =IF(Datos!E35>=0.9,"🟢 EXCELENTE",IF(Datos!E35>=0.7,"🟡 EN CAMINO",IF(Datos!E35>=0.5,"🟠 ALERTA","🔴 CRÍTICO")))
B26: TOTAL TECNOQUIMICAS | C26: =Datos!C28+Datos!C29+Datos!C30+Datos!C31+Datos!C32+Datos!C33+Datos!C34+Datos!C35 | D26: =Datos!D28+Datos!D29+Datos!D30+Datos!D31+Datos!D32+Datos!D33+Datos!D34+Datos!D35 | E26: =D26/C26 | F26: =Datos!G28+Datos!G29+Datos!G30+Datos!G31+Datos!G32+Datos!G33+Datos!G34+Datos!G35 | G26: =Datos!F28+Datos!F29+Datos!F30+Datos!F31+Datos!F32+Datos!F33+Datos!F34+Datos!F35 | H26: =SUM(H18:H25) | I26: =F26/G26
B28: ANÁLISIS DE GESTIÓN
B29: ="▶ Venta del día en progreso: "&TEXT((Datos!D28+Datos!D29+Datos!D30+Datos!D31+Datos!D32+Datos!D33+Datos!D34+Datos!D35)/(Datos!C28+Datos!C29+Datos!C30+Datos!C31+Datos!C32+Datos!C33+Datos!C34+Datos!C35),"0.0%")&" del presupuesto."
B30: =IF(COUNTIF(Datos!H28:H35,">="&1)=8,"✔ "&8&" de 8 asesores cumplen meta. Excedente de "&ABS((Datos!G28+Datos!G29+Datos!G30+Datos!G31+Datos!G32+Datos!G33+Datos!G34+Datos!G35)-(Datos!F28+Datos!F29+Datos!F30+Datos!F31+Datos!F32+Datos!F33+Datos!F34+Datos!F35))&" pedidos sobre el objetivo.","▶ "&COUNTIF(Datos!H28:H35,">="&1)&" de 8 asesores cumplen meta. Pendiente cerrar "&MAX(0,(Datos!F28+Datos!F29+Datos!F30+Datos!F31+Datos!F32+Datos!F33+Datos!F34+Datos!F35)-(Datos!G28+Datos!G29+Datos!G30+Datos!G31+Datos!G32+Datos!G33+Datos!G34+Datos!G35))&" pedidos.")
B31: ="★ Mejor asesor: "&IF(ISNUMBER(VALUE(LEFT(INDEX(Datos!B28:B35,MATCH(MAX(Datos!D28:D35),Datos!D28:D35,0)),4))),MID(INDEX(Datos!B28:B35,MATCH(MAX(Datos!D28:D35),Datos!D28:D35,0)),6,100),INDEX(Datos!B28:B35,MATCH(MAX(Datos!D28:D35),Datos!D28:D35,0)))&" con "&TEXT(MAX(Datos!D28:D35),"$#,##0")&" y "&INDEX(Datos!G28:G35,MATCH(MAX(Datos!D28:D35),Datos!D28:D35,0))&" facturas."
B32: ="⚠ Asesor con menor venta: "&IF(ISNUMBER(VALUE(LEFT(INDEX(Datos!B28:B35,MATCH(MIN(Datos!D28:D35),Datos!D28:D35,0)),4))),MID(INDEX(Datos!B28:B35,MATCH(MIN(Datos!D28:D35),Datos!D28:D35,0)),6,100),INDEX(Datos!B28:B35,MATCH(MIN(Datos!D28:D35),Datos!D28:D35,0)))&" con "&TEXT(MIN(Datos!D28:D35),"$#,##0")&" ("&TEXT(MIN(Datos!E28:E35),"0.0%")&" del ppto)."

Sheet Clientes Especiales
B1: UNIDAD DE NEGOCIO — CLIENTES ESPECIALES
B4: Corte: MARZO 2025 | Asesores: 2 | Informe automático
B6: VENTA DÍA | D6: PRESUPUESTO DÍA | F6: % CUMPL. PPTO | H6: % CUMPL. PLAN
B7: =TEXT((Datos!D36+Datos!#REF!)/1000000,"$#,##0.00")&"M" | D7: =TEXT((Datos!C36+Datos!#REF!)/1000000,"$#,##0.00")&"M" | F7: =TEXT((Datos!D36+Datos!#REF!)/(Datos!C36+Datos!#REF!),"0.0%") | H7: =TEXT((Datos!G36+Datos!#REF!)/(Datos!F36+Datos!#REF!),"0.0%")
B11: FACTURAS / OBJETIVO | D11: CUMPLEN META PLAN | F11: MEJOR ASESOR | H11: PEDIDOS FALTANTES
B12: =TEXT(Datos!G36+Datos!#REF!,"0")&" / "&TEXT(Datos!F36+Datos!#REF!,"0") | D12: =TEXT(COUNTIF(Datos!H36:H36,">="&1),"0")&" / "&"2" | F12: =IF(ISNUMBER(VALUE(LEFT(INDEX(Datos!B36:B36,MATCH(MAX(Datos!D36:D36),Datos!D36:D36,0)),4))),MID(INDEX(Datos!B36:B36,MATCH(MAX(Datos!D36:D36),Datos!D36:D36,0)),6,100),INDEX(Datos!B36:B36,MATCH(MAX(Datos!D36:D36),Datos!D36:D36,0))) | H12: =TEXT(ABS(Datos!F36+Datos!#REF!-Datos!G36+Datos!#REF!),"0")&IF(Datos!G36+Datos!#REF!>=Datos!F36+Datos!#REF!," excedente"," pedidos")
B16: DETALLE DE ASESORES — CLIENTES ESPECIALES
B17: Asesor Comercial | C17: Ppto Día ($) | D17: Venta Día ($) | E17: % Cumpl. Ppto | F17: # Facturas | G17: Obj. Plan | H17: Faltante | I17: Estado Plan
B18: =IF(ISNUMBER(VALUE(LEFT(Datos!B36,4))),MID(Datos!B36,6,100),Datos!B36) | C18: =Datos!C36 | D18: =Datos!D36 | E18: =Datos!E36 | F18: =Datos!G36 | G18: =Datos!F36 | H18: =Datos!I36 | I18: =IF(Datos!E36>=0.9,"🟢 EXCELENTE",IF(Datos!E36>=0.7,"🟡 EN CAMINO",IF(Datos!E36>=0.5,"🟠 ALERTA","🔴 CRÍTICO")))
B19: =IF(ISNUMBER(VALUE(LEFT(Datos!#REF!,4))),MID(Datos!#REF!,6,100),Datos!#REF!) | C19: =Datos!#REF! | D19: =Datos!#REF! | E19: =Datos!#REF! | F19: =Datos!#REF! | G19: =Datos!#REF! | H19: =Datos!#REF! | I19: =IF(Datos!#REF!>=0.9,"🟢 EXCELENTE",IF(Datos!#REF!>=0.7,"🟡 EN CAMINO",IF(Datos!#REF!>=0.5,"🟠 ALERTA","🔴 CRÍTICO")))
B20: TOTAL CLIENTES ESPECIALES | C20: =Datos!C36+Datos!#REF! | D20: =Datos!D36+Datos!#REF! | E20: =D20/C20 | F20: =Datos!G36+Datos!#REF! | G20: =Datos!F36+Datos!#REF! | H20: =SUM(H18:H19) | I20: =F20/G20
B22: ANÁLISIS DE GESTIÓN
B23: ="▶ Venta del día en progreso: "&TEXT((Datos!D36+Datos!#REF!)/(Datos!C36+Datos!#REF!),"0.0%")&" del presupuesto."
B24: =IF(COUNTIF(Datos!H36:H36,">="&1)=2,"✔ "&2&" de 2 asesores cumplen meta. Excedente de "&ABS((Datos!G36+Datos!#REF!)-(Datos!F36+Datos!#REF!))&" pedidos sobre el objetivo.","▶ "&COUNTIF(Datos!H36:H36,">="&1)&" de 2 asesores cumplen meta. Pendiente cerrar "&MAX(0,(Datos!F36+Datos!#REF!)-(Datos!G36+Datos!#REF!))&" pedidos.")
B25: ="★ Mejor asesor: "&IF(ISNUMBER(VALUE(LEFT(INDEX(Datos!B36:B36,MATCH(MAX(Datos!D36:D36),Datos!D36:D36,0)),4))),MID(INDEX(Datos!B36:B36,MATCH(MAX(Datos!D36:D36),Datos!D36:D36,0)),6,100),INDEX(Datos!B36:B36,MATCH(MAX(Datos!D36:D36),Datos!D36:D36,0)))&" con "&TEXT(MAX(Datos!D36:D36),"$#,##0")&" y "&INDEX(Datos!G36:G36,MATCH(MAX(Datos!D36:D36),Datos!D36:D36,0))&" facturas."
B26: ="⚠ Asesor con menor venta: "&IF(ISNUMBER(VALUE(LEFT(INDEX(Datos!B36:B36,MATCH(MIN(Datos!D36:D36),Datos!D36:D36,0)),4))),MID(INDEX(Datos!B36:B36,MATCH(MIN(Datos!D36:D36),Datos!D36:D36,0)),6,100),INDEX(Datos!B36:B36,MATCH(MIN(Datos!D36:D36),Datos!D36:D36,0)))&" con "&TEXT(MIN(Datos!D36:D36),"$#,##0")&" ("&TEXT(MIN(Datos!E36:E36),"0.0%")&" del ppto)."

Sheet Brinsa
B1: UNIDAD DE NEGOCIO — BRINSA
B4: Corte: MARZO 2025 | Asesores: 8 | Informe automático
B6: VENTA DÍA | D6: PRESUPUESTO DÍA | F6: % CUMPL. PPTO | H6: % CUMPL. PLAN
B7: =TEXT((Datos!D37+Datos!D38+Datos!D39+Datos!D40+Datos!D41+Datos!D42+Datos!D43+Datos!D44)/1000000,"$#,##0.00")&"M" | D7: =TEXT((Datos!C37+Datos!C38+Datos!C39+Datos!C40+Datos!C41+Datos!C42+Datos!C43+Datos!C44)/1000000,"$#,##0.00")&"M" | F7: =TEXT((Datos!D37+Datos!D38+Datos!D39+Datos!D40+Datos!D41+Datos!D42+Datos!D43+Datos!D44)/(Datos!C37+Datos!C38+Datos!C39+Datos!C40+Datos!C41+Datos!C42+Datos!C43+Datos!C44),"0.0%") | H7: =TEXT((Datos!G37+Datos!G38+Datos!G39+Datos!G40+Datos!G41+Datos!G42+Datos!G43+Datos!G44)/(Datos!F37+Datos!F38+Datos!F39+Datos!F40+Datos!F41+Datos!F42+Datos!F43+Datos!F44),"0.0%")
B11: FACTURAS / OBJETIVO | D11: CUMPLEN META PLAN | F11: MEJOR ASESOR | H11: PEDIDOS FALTANTES
B12: =TEXT(Datos!G37+Datos!G38+Datos!G39+Datos!G40+Datos!G41+Datos!G42+Datos!G43+Datos!G44,"0")&" / "&TEXT(Datos!F37+Datos!F38+Datos!F39+Datos!F40+Datos!F41+Datos!F42+Datos!F43+Datos!F44,"0") | D12: =TEXT(COUNTIF(Datos!H37:H44,">="&1),"0")&" / "&"8" | F12: =IF(ISNUMBER(VALUE(LEFT(INDEX(Datos!B37:B44,MATCH(MAX(Datos!D37:D44),Datos!D37:D44,0)),4))),MID(INDEX(Datos!B37:B44,MATCH(MAX(Datos!D37:D44),Datos!D37:D44,0)),6,100),INDEX(Datos!B37:B44,MATCH(MAX(Datos!D37:D44),Datos!D37:D44,0))) | H12: =TEXT(ABS(Datos!F37+Datos!F38+Datos!F39+Datos!F40+Datos!F41+Datos!F42+Datos!F43+Datos!F44-Datos!G37+Datos!G38+Datos!G39+Datos!G40+Datos!G41+Datos!G42+Datos!G43+Datos!G44),"0")&IF(Datos!G37+Datos!G38+Datos!G39+Datos!G40+Datos!G41+Datos!G42+Datos!G43+Datos!G44>=Datos!F37+Datos!F38+Datos!F39+Datos!F40+Datos!F41+Datos!F42+Datos!F43+Datos!F44," excedente"," pedidos")
B16: DETALLE DE ASESORES — BRINSA
B17: Asesor Comercial | C17: Ppto Día ($) | D17: Venta Día ($) | E17: % Cumpl. Ppto | F17: # Facturas | G17: Obj. Plan | H17: Faltante | I17: Estado Plan
B18: =IF(ISNUMBER(VALUE(LEFT(Datos!B37,4))),MID(Datos!B37,6,100),Datos!B37) | C18: =Datos!C37 | D18: =Datos!D37 | E18: =Datos!E37 | F18: =Datos!G37 | G18: =Datos!F37 | H18: =Datos!I37 | I18: =IF(Datos!E37>=0.9,"🟢 EXCELENTE",IF(Datos!E37>=0.7,"🟡 EN CAMINO",IF(Datos!E37>=0.5,"🟠 ALERTA","🔴 CRÍTICO")))
B19: =IF(ISNUMBER(VALUE(LEFT(Datos!B38,4))),MID(Datos!B38,6,100),Datos!B38) | C19: =Datos!C38 | D19: =Datos!D38 | E19: =Datos!E38 | F19: =Datos!G38 | G19: =Datos!F38 | H19: =Datos!I38 | I19: =IF(Datos!E38>=0.9,"🟢 EXCELENTE",IF(Datos!E38>=0.7,"🟡 EN CAMINO",IF(Datos!E38>=0.5,"🟠 ALERTA","🔴 CRÍTICO")))
B20: =IF(ISNUMBER(VALUE(LEFT(Datos!B39,4))),MID(Datos!B39,6,100),Datos!B39) | C20: =Datos!C39 | D20: =Datos!D39 | E20: =Datos!E39 | F20: =Datos!G39 | G20: =Datos!F39 | H20: =Datos!I39 | I20: =IF(Datos!E39>=0.9,"🟢 EXCELENTE",IF(Datos!E39>=0.7,"🟡 EN CAMINO",IF(Datos!E39>=0.5,"🟠 ALERTA","🔴 CRÍTICO")))
B21: =IF(ISNUMBER(VALUE(LEFT(Datos!B40,4))),MID(Datos!B40,6,100),Datos!B40) | C21: =Datos!C40 | D21: =Datos!D40 | E21: =Datos!E40 | F21: =Datos!G40 | G21: =Datos!F40 | H21: =Datos!I40 | I21: =IF(Datos!E40>=0.9,"🟢 EXCELENTE",IF(Datos!E40>=0.7,"🟡 EN CAMINO",IF(Datos!E40>=0.5,"🟠 ALERTA","🔴 CRÍTICO")))
B22: =IF(ISNUMBER(VALUE(LEFT(Datos!B41,4))),MID(Datos!B41,6,100),Datos!B41) | C22: =Datos!C41 | D22: =Datos!D41 | E22: =Datos!E41 | F22: =Datos!G41 | G22: =Datos!F41 | H22: =Datos!I41 | I22: =IF(Datos!E41>=0.9,"🟢 EXCELENTE",IF(Datos!E41>=0.7,"🟡 EN CAMINO",IF(Datos!E41>=0.5,"🟠 ALERTA","🔴 CRÍTICO")))
B23: =IF(ISNUMBER(VALUE(LEFT(Datos!B42,4))),MID(Datos!B42,6,100),Datos!B42) | C23: =Datos!C42 | D23: =Datos!D42 | E23: =Datos!E42 | F23: =Datos!G42 | G23: =Datos!F42 | H23: =Datos!I42 | I23: =IF(Datos!E42>=0.9,"🟢 EXCELENTE",IF(Datos!E42>=0.7,"🟡 EN CAMINO",IF(Datos!E42>=0.5,"🟠 ALERTA","🔴 CRÍTICO")))
B24: =IF(ISNUMBER(VALUE(LEFT(Datos!B43,4))),MID(Datos!B43,6,100),Datos!B43) | C24: =Datos!C43 | D24: =Datos!D43 | E24: =Datos!E43 | F24: =Datos!G43 | G24: =Datos!F43 | H24: =Datos!I43 | I24: =IF(Datos!E43>=0.9,"🟢 EXCELENTE",IF(Datos!E43>=0.7,"🟡 EN CAMINO",IF(Datos!E43>=0.5,"🟠 ALERTA","🔴 CRÍTICO")))
B25: =IF(ISNUMBER(VALUE(LEFT(Datos!B44,4))),MID(Datos!B44,6,100),Datos!B44) | C25: =Datos!C44 | D25: =Datos!D44 | E25: =Datos!E44 | F25: =Datos!G44 | G25: =Datos!F44 | H25: =Datos!I44 | I25: =IF(Datos!E44>=0.9,"🟢 EXCELENTE",IF(Datos!E44>=0.7,"🟡 EN CAMINO",IF(Datos!E44>=0.5,"🟠 ALERTA","🔴 CRÍTICO")))
B26: TOTAL BRINSA | C26: =Datos!C37+Datos!C38+Datos!C39+Datos!C40+Datos!C41+Datos!C42+Datos!C43+Datos!C44 | D26: =Datos!D37+Datos!D38+Datos!D39+Datos!D40+Datos!D41+Datos!D42+Datos!D43+Datos!D44 | E26: =D26/C26 | F26: =Datos!G37+Datos!G38+Datos!G39+Datos!G40+Datos!G41+Datos!G42+Datos!G43+Datos!G44 | G26: =Datos!F37+Datos!F38+Datos!F39+Datos!F40+Datos!F41+Datos!F42+Datos!F43+Datos!F44 | H26: =SUM(H18:H25) | I26: =F26/G26
B28: ANÁLISIS DE GESTIÓN
B29: ="▶ Venta del día en progreso: "&TEXT((Datos!D37+Datos!D38+Datos!D39+Datos!D40+Datos!D41+Datos!D42+Datos!D43+Datos!D44)/(Datos!C37+Datos!C38+Datos!C39+Datos!C40+Datos!C41+Datos!C42+Datos!C43+Datos!C44),"0.0%")&" del presupuesto."
B30: =IF(COUNTIF(Datos!H37:H44,">="&1)=8,"✔ "&8&" de 8 asesores cumplen meta. Excedente de "&ABS((Datos!G37+Datos!G38+Datos!G39+Datos!G40+Datos!G41+Datos!G42+Datos!G43+Datos!G44)-(Datos!F37+Datos!F38+Datos!F39+Datos!F40+Datos!F41+Datos!F42+Datos!F43+Datos!F44))&" pedidos sobre el objetivo.","▶ "&COUNTIF(Datos!H37:H44,">="&1)&" de 8 asesores cumplen meta. Pendiente cerrar "&MAX(0,(Datos!F37+Datos!F38+Datos!F39+Datos!F40+Datos!F41+Datos!F42+Datos!F43+Datos!F44)-(Datos!G37+Datos!G38+Datos!G39+Datos!G40+Datos!G41+Datos!G42+Datos!G43+Datos!G44))&" pedidos.")
B31: ="★ Mejor asesor: "&IF(ISNUMBER(VALUE(LEFT(INDEX(Datos!B37:B44,MATCH(MAX(Datos!D37:D44),Datos!D37:D44,0)),4))),MID(INDEX(Datos!B37:B44,MATCH(MAX(Datos!D37:D44),Datos!D37:D44,0)),6,100),INDEX(Datos!B37:B44,MATCH(MAX(Datos!D37:D44),Datos!D37:D44,0)))&" con "&TEXT(MAX(Datos!D37:D44),"$#,##0")&" y "&INDEX(Datos!G37:G44,MATCH(MAX(Datos!D37:D44),Datos!D37:D44,0))&" facturas."
B32: ="⚠ Asesor con menor venta: "&IF(ISNUMBER(VALUE(LEFT(INDEX(Datos!B37:B44,MATCH(MIN(Datos!D37:D44),Datos!D37:D44,0)),4))),MID(INDEX(Datos!B37:B44,MATCH(MIN(Datos!D37:D44),Datos!D37:D44,0)),6,100),INDEX(Datos!B37:B44,MATCH(MIN(Datos!D37:D44),Datos!D37:D44,0)))&" con "&TEXT(MIN(Datos!D37:D44),"$#,##0")&" ("&TEXT(MIN(Datos!E37:E44),"0.0%")&" del ppto)."

Sheet Colombina Helados
B1: UNIDAD DE NEGOCIO — COLOMBINA HELADOS
B4: Corte: MARZO 2025 | Asesores: 2 | Informe automático
B6: VENTA DÍA | D6: PRESUPUESTO DÍA | F6: % CUMPL. PPTO | H6: % CUMPL. PLAN
B7: =TEXT((Datos!D2+Datos!D3)/1000000,"$#,##0.00")&"M" | D7: =TEXT((Datos!C2+Datos!C3)/1000000,"$#,##0.00")&"M" | F7: =TEXT((Datos!D2+Datos!D3)/(Datos!C2+Datos!C3),"0.0%") | H7: =TEXT((Datos!G2+Datos!G3)/(Datos!F2+Datos!F3),"0.0%")
B11: FACTURAS / OBJETIVO | D11: CUMPLEN META PLAN | F11: MEJOR ASESOR | H11: PEDIDOS FALTANTES
B12: =TEXT(Datos!G2+Datos!G3,"0")&" / "&TEXT(Datos!F2+Datos!F3,"0") | D12: =TEXT(COUNTIF(Datos!H2:H3,">="&1),"0")&" / "&"2" | F12: =IF(ISNUMBER(VALUE(LEFT(INDEX(Datos!B2:B3,MATCH(MAX(Datos!D2:D3),Datos!D2:D3,0)),4))),MID(INDEX(Datos!B2:B3,MATCH(MAX(Datos!D2:D3),Datos!D2:D3,0)),6,100),INDEX(Datos!B2:B3,MATCH(MAX(Datos!D2:D3),Datos!D2:D3,0))) | H12: =TEXT(ABS(Datos!F2+Datos!F3-Datos!G2+Datos!G3),"0")&IF(Datos!G2+Datos!G3>=Datos!F2+Datos!F3," excedente"," pedidos")
B16: DETALLE DE ASESORES — COLOMBINA HELADOS
B17: Asesor Comercial | C17: Ppto Día ($) | D17: Venta Día ($) | E17: % Cumpl. Ppto | F17: # Facturas | G17: Obj. Plan | H17: Faltante | I17: Estado Plan
B18: =IF(ISNUMBER(VALUE(LEFT(Datos!B2,4))),MID(Datos!B2,6,100),Datos!B2) | C18: =Datos!C2 | D18: =Datos!D2 | E18: =Datos!E2 | F18: =Datos!G2 | G18: =Datos!F2 | H18: =Datos!I2 | I18: =IF(Datos!E2>=0.9,"🟢 EXCELENTE",IF(Datos!E2>=0.7,"🟡 EN CAMINO",IF(Datos!E2>=0.5,"🟠 ALERTA","🔴 CRÍTICO")))
B19: =IF(ISNUMBER(VALUE(LEFT(Datos!B3,4))),MID(Datos!B3,6,100),Datos!B3) | C19: =Datos!C3 | D19: =Datos!D3 | E19: =Datos!E3 | F19: =Datos!G3 | G19: =Datos!F3 | H19: =Datos!I3 | I19: =IF(Datos!E3>=0.9,"🟢 EXCELENTE",IF(Datos!E3>=0.7,"🟡 EN CAMINO",IF(Datos!E3>=0.5,"🟠 ALERTA","🔴 CRÍTICO")))
B20: TOTAL COLOMBINA HELADOS | C20: =Datos!C2+Datos!C3 | D20: =Datos!D2+Datos!D3 | E20: =D20/C20 | F20: =Datos!G2+Datos!G3 | G20: =Datos!F2+Datos!F3 | H20: =SUM(H18:H19) | I20: =F20/G20
B22: ANÁLISIS DE GESTIÓN
B23: ="▶ Venta del día en progreso: "&TEXT((Datos!D2+Datos!D3)/(Datos!C2+Datos!C3),"0.0%")&" del presupuesto."
B24: =IF(COUNTIF(Datos!H2:H3,">="&1)=2,"✔ "&2&" de 2 asesores cumplen meta. Excedente de "&ABS((Datos!G2+Datos!G3)-(Datos!F2+Datos!F3))&" pedidos sobre el objetivo.","▶ "&COUNTIF(Datos!H2:H3,">="&1)&" de 2 asesores cumplen meta. Pendiente cerrar "&MAX(0,(Datos!F2+Datos!F3)-(Datos!G2+Datos!G3))&" pedidos.")
B25: ="★ Mejor asesor: "&IF(ISNUMBER(VALUE(LEFT(INDEX(Datos!B2:B3,MATCH(MAX(Datos!D2:D3),Datos!D2:D3,0)),4))),MID(INDEX(Datos!B2:B3,MATCH(MAX(Datos!D2:D3),Datos!D2:D3,0)),6,100),INDEX(Datos!B2:B3,MATCH(MAX(Datos!D2:D3),Datos!D2:D3,0)))&" con "&TEXT(MAX(Datos!D2:D3),"$#,##0")&" y "&INDEX(Datos!G2:G3,MATCH(MAX(Datos!D2:D3),Datos!D2:D3,0))&" facturas."
B26: ="⚠ Asesor con menor venta: "&IF(ISNUMBER(VALUE(LEFT(INDEX(Datos!B2:B3,MATCH(MIN(Datos!D2:D3),Datos!D2:D3,0)),4))),MID(INDEX(Datos!B2:B3,MATCH(MIN(Datos!D2:D3),Datos!D2:D3,0)),6,100),INDEX(Datos!B2:B3,MATCH(MIN(Datos!D2:D3),Datos!D2:D3,0)))&" con "&TEXT(MIN(Datos!D2:D3),"$#,##0")&" ("&TEXT(MIN(Datos!E2:E3),"0.0%")&" del ppto)."

Sheet Alimentos Polar
B1: UNIDAD DE NEGOCIO — ALIMENTOS POLAR
B4: Corte: MARZO 2025 | Asesores: 4 | Informe automático
B6: VENTA DÍA | D6: PRESUPUESTO DÍA | F6: % CUMPL. PPTO | H6: % CUMPL. PLAN
B7: =TEXT((Datos!D45+Datos!D46+Datos!D47+Datos!D48)/1000000,"$#,##0.00")&"M" | D7: =TEXT((Datos!C45+Datos!C46+Datos!C47+Datos!C48)/1000000,"$#,##0.00")&"M" | F7: =TEXT((Datos!D45+Datos!D46+Datos!D47+Datos!D48)/(Datos!C45+Datos!C46+Datos!C47+Datos!C48),"0.0%") | H7: =TEXT((Datos!G45+Datos!G46+Datos!G47+Datos!G48)/(Datos!F45+Datos!F46+Datos!F47+Datos!F48),"0.0%")
B11: FACTURAS / OBJETIVO | D11: CUMPLEN META PLAN | F11: MEJOR ASESOR | H11: PEDIDOS FALTANTES
B12: =TEXT(Datos!G45+Datos!G46+Datos!G47+Datos!G48,"0")&" / "&TEXT(Datos!F45+Datos!F46+Datos!F47+Datos!F48,"0") | D12: =TEXT(COUNTIF(Datos!H45:H48,">="&1),"0")&" / "&"4" | F12: =IF(ISNUMBER(VALUE(LEFT(INDEX(Datos!B45:B48,MATCH(MAX(Datos!D45:D48),Datos!D45:D48,0)),4))),MID(INDEX(Datos!B45:B48,MATCH(MAX(Datos!D45:D48),Datos!D45:D48,0)),6,100),INDEX(Datos!B45:B48,MATCH(MAX(Datos!D45:D48),Datos!D45:D48,0))) | H12: =TEXT(ABS(Datos!F45+Datos!F46+Datos!F47+Datos!F48-Datos!G45+Datos!G46+Datos!G47+Datos!G48),"0")&IF(Datos!G45+Datos!G46+Datos!G47+Datos!G48>=Datos!F45+Datos!F46+Datos!F47+Datos!F48," excedente"," pedidos")
B16: DETALLE DE ASESORES — ALIMENTOS POLAR
B17: Asesor Comercial | C17: Ppto Día ($) | D17: Venta Día ($) | E17: % Cumpl. Ppto | F17: # Facturas | G17: Obj. Plan | H17: Faltante | I17: Estado Plan
B18: =IF(ISNUMBER(VALUE(LEFT(Datos!B45,4))),MID(Datos!B45,6,100),Datos!B45) | C18: =Datos!C45 | D18: =Datos!D45 | E18: =Datos!E45 | F18: =Datos!G45 | G18: =Datos!F45 | H18: =Datos!I45 | I18: =IF(Datos!E45>=0.9,"🟢 EXCELENTE",IF(Datos!E45>=0.7,"🟡 EN CAMINO",IF(Datos!E45>=0.5,"🟠 ALERTA","🔴 CRÍTICO")))
B19: =IF(ISNUMBER(VALUE(LEFT(Datos!B46,4))),MID(Datos!B46,6,100),Datos!B46) | C19: =Datos!C46 | D19: =Datos!D46 | E19: =Datos!E46 | F19: =Datos!G46 | G19: =Datos!F46 | H19: =Datos!I46 | I19: =IF(Datos!E46>=0.9,"🟢 EXCELENTE",IF(Datos!E46>=0.7,"🟡 EN CAMINO",IF(Datos!E46>=0.5,"🟠 ALERTA","🔴 CRÍTICO")))
